Workbook
Name Age_Cap: '01_Catalog_&_Parameters'!$B$9
Name Aggregate_MOQ: '01_Catalog_&_Parameters'!$F$9
Name AIS_Payback: '01_Catalog_&_Parameters'!$F$8
Name CBM_20GP: '01_Catalog_&_Parameters'!$B$10
Name CBM_40HC: '01_Catalog_&_Parameters'!$B$11
Name DOS_Cap: '01_Catalog_&_Parameters'!$B$12
Name Fee_Min_Weekly: '01_Catalog_&_Parameters'!$F$6
Name Fee_Threshold: '01_Catalog_&_Parameters'!$F$5
Name Gamma_Cannib: '01_Catalog_&_Parameters'!$F$4
Name Hero_Weekly: '01_Catalog_&_Parameters'!$F$12
Name Kappa_Cred: '01_Catalog_&_Parameters'!$F$3
Name L1_Mean: '01_Catalog_&_Parameters'!$B$3
Name L1_Std: '01_Catalog_&_Parameters'!$B$4
Name L2_Mean: '01_Catalog_&_Parameters'!$B$5
Name L2_Std: '01_Catalog_&_Parameters'!$B$6
Name LCL_Breakeven: '01_Catalog_&_Parameters'!$F$10
Name Removal_Fee: '01_Catalog_&_Parameters'!$F$7
Name Review_Days: '01_Catalog_&_Parameters'!$B$8
Name Shield_Days: '01_Catalog_&_Parameters'!$B$7
Name Snapshot_Date: '01_Catalog_&_Parameters'!$B$13
Name TopUp_Reserve: '01_Catalog_&_Parameters'!$F$11

Sheet 00_Exec_Control_Tower
A1: OMNICHANNEL INVENTORY CONTROL TOWER · WEEKLY S&OP
A2: Snapshot 2026-10-25 · Deterministic seed 42 · 160 child FNSKUs · 365-day history · sign-off package generated from live formulas on tabs 02-05
A4: EXECUTIVE KPI CONTROL TOWER
A5: Metric | B5: Value | C5: Unit | D5: Source | E5: Threshold / policy | F5: Status
A6: Catalog child FNSKUs | B6: =COUNTA(tbl_Catalog[sku_id]) -> 160 | C6: SKUs | D6: Tab 01 · tbl_Catalog | E6: 160 target | F6: =IF(B6=160,"OK","REVIEW") -> OK
A7: FBA available units | B7: =SUM('03_FBA_Nivel1_Transfer'!$D$5:$D$164) -> 19980 | C7: units | D7: Tab 03 · Col D | E7: Physical stock | F7: =IF(B7>0,"OK","REVIEW") -> OK
A8: 3PL on-hand units | B8: =SUM('04_Factory_Nivel2_PO_&_CBM'!$D$5:$D$164) -> 35827 | C8: units | D8: Tab 04 · Col D | E8: Upstream pool | F8: =IF(B8>0,"OK","REVIEW") -> OK
A9: Open PO units | B9: =SUM('04_Factory_Nivel2_PO_&_CBM'!$AA$5:$AA$164) -> 50500 | C9: units | D9: Tab 04 · Col AA | E9: In-transit / production | F9: =IF(B9>0,"OK","REVIEW") -> OK
A10: Inventory value at landed cost | B10: =SUMPRODUCT(tbl_Catalog[landed_cost],('03_FBA_Nivel1_Transfer'!D5:D164+'04_Factory_Nivel2_PO_&_CBM'!D5:D164+'04_Factory_Nivel2_PO_&_CBM'!AA5:AA164)) -> 652675.1 | C10: USD | D10: Catalog × system units | E10: Working-capital exposure | F10: =IF(B10>0,"OK","REVIEW") -> OK
A11: FNSKUs with 30d HDoS < 14d | B11: =COUNTIF('03_FBA_Nivel1_Transfer'!$F$5:$F$164,"<14") -> 53 | C11: SKUs | D11: Tab 03 · Col F | E11: Critical stockout band | F11: =IF(B11=0,"OK","CRITICAL") -> CRITICAL
A12: Non-exempt FNSKUs in 14-28d fee band | B12: =COUNTIFS('03_FBA_Nivel1_Transfer'!$F$5:$F$164,">=14",'03_FBA_Nivel1_Transfer'!$G$5:$G$164,"<28",'03_FBA_Nivel1_Transfer'!$F$5:$F$164,"<28",'03_FBA_Nivel1_Transfer'!$J$5:$J$164,FALSE) -> 8 | C12: SKUs | D12: Tab 03 · Col F/G/J | E12: 30-day window; charge model uses max(30d, 90d) | F12: =IF(B12=0,"OK","ACTION") -> ACTION
A13: 30-day low-inventory fee exposure | B13: =SUM('03_FBA_Nivel1_Transfer'!$Z$5:$Z$164) -> 3442 | C13: USD | D13: Tab 03 · Col Z | E13: $0.32 / $0.63 / $0.89 per unit | F13: =IF(B13=0,"OK","ACTION") -> ACTION
A14: 3PL → FBA transfer cartons | B14: =SUM('03_FBA_Nivel1_Transfer'!$T$5:$T$164) -> 147 | C14: cartons | D14: Tab 03 · Col T | E14: Master-carton multiples | F14: =IF(B14>0,"READY","REVIEW") -> READY
A15: 3PL → FBA transfer units | B15: =SUM('03_FBA_Nivel1_Transfer'!$S$5:$S$164) -> 11450 | C15: units | D15: Tab 03 · Col S | E15: Age-safe ≤120d | F15: =IF(B15>0,"READY","REVIEW") -> READY
A16: Factory PO units | B16: =SUM('04_Factory_Nivel2_PO_&_CBM'!$U$5:$U$164) -> 41850 | C16: units | D16: Tab 04 · Col U | E16: Aggregate MOQ ≥5,000 | F16: =IF(B16>=Aggregate_MOQ,"MET","GAP") -> MET
A17: Factory PO cartons | B17: =SUM('04_Factory_Nivel2_PO_&_CBM'!$V$5:$V$164) -> 492 | C17: cartons | D17: Tab 04 · Col V | E17: Integer master cartons | F17: =IF(B17>0,"READY","REVIEW") -> READY
A18: Container volume | B18: =SUM('04_Factory_Nivel2_PO_&_CBM'!$W$5:$W$164) -> 28.77 | C18: CBM | D18: Tab 04 · Col W | E18: 20' GP = 28.8 CBM | F18: =IF(B18>=LCL_Breakeven,"FCL","LCL") -> FCL
A19: Container utilisation | B19: =IF(CBM_20GP>0,B18/CBM_20GP,0) -> 0.99895833 | C19: % | D19: CBM / 28.8 | E19: ≥95% optimal fill | F19: =IF(B19>=0.95,"OPTIMAL","DEAD ZONE") -> OPTIMAL
A20: Aggregate PO MOQ | B20: =IF(B16>=Aggregate_MOQ,"MET","GAP: "&TEXT(Aggregate_MOQ-B16,"#,##0")&" u") -> MET | C20: status | D20: Tab 04 · Col U | E20: 5,000-unit floor | F20: =IF(B16>=Aggregate_MOQ,"MET","GAP") -> MET
A21: Projected monthly AIS | B21: =SUM('05_Fee_Risk_Audit'!$O$5:$O$164) -> 38.629976 | C21: USD | D21: Tab 05 · Col O | E21: Aged inventory surcharge | F21: =IF(B21>0,"MONITOR","OK") -> MONITOR
A22: Removal recommendations | B22: =COUNTIF('05_Fee_Risk_Audit'!$S$5:$S$164,"EXECUTE REMOVAL") -> 2 | C22: SKUs | D22: Tab 05 · Col S | E22: Payback ≤12 months | F22: =IF(B22>0,"ACTION","OK") -> ACTION
A23: Annualised AIS exposure | B23: =SUM('05_Fee_Risk_Audit'!$T$5:$T$164) -> 463.55971 | C23: USD | D23: Tab 05 · Col T | E23: 12 × monthly AIS | F23: =IF(B23>0,"MONITOR","OK") -> MONITOR
A24: Combined fee + AIS exposure | B24: =B13+B21 -> 3480.63 | C24: USD | D24: Tabs 03 + 05 | E24: Weekly + monthly leakage | F24: =IF(B24>0,"MONITOR","OK") -> MONITOR
A26: EXCEPTION MATRIX · WHAT REQUIRES A DECISION THIS WEEK
A27: Severity | B27: Domain | C27: Exception | D27: Count | E27: Owner | F27: Required action
A28: CRITICAL | B28: Demand | C28: FNSKUs with HDoS < 14 days | D28: =B11 -> 53 | E28: Inventory Ops | F28: Expedite SPD / release 3PL cartons before fee lock
A29: HIGH | B29: Fee | C29: Non-exempt FNSKUs in 14-28d band | D29: =B12 -> 8 | E29: Finance + Ops | F29: Transfer now; do not wait for the next Monday cycle
A30: HIGH | B30: Aging | C30: Units >180 days at FBA | D30: =SUM('05_Fee_Risk_Audit'!$W$5:$W$164) -> 2008 | E30: Compliance | F30: Removal or 25% markdown before the 14th, 23:59 PT
A31: MEDIUM | B31: Container | C31: Factory cartons deferred to next cycle | D31: =SUM('04_Factory_Nivel2_PO_&_CBM'!$AB$5:$AB$164) -> 1236 | E31: Logistics | F31: Roll into next Monday's 20' GP allocation
A32: MEDIUM | B32: MOQ | C32: Lines with MOQ-driven DOS override | D32: =COUNTIF('04_Factory_Nivel2_PO_&_CBM'!$Z$5:$Z$164,"MOQ OVERRIDE") -> 0 | E32: Procurement | F32: Negotiate lower MOQ or split production lots
A33: LOW | B33: Analytics | C33: FNSKUs with positive unconstraining uplift | D33: =COUNTIF('02_Demand_Unconstraining'!$U$5:$U$164,">0") -> 63 | E33: Demand Planning | F33: Audit censored-demand assumptions in Tab 02
A35: CONTAINER FILL GAUGE
A36: ="["&REPT("█",ROUND(B19*20,0))&REPT("·",20-ROUND(B19*20,0))&"] "&TEXT(B19,"0.0%")&" · "&TEXT(B18,"0.000")&" / "&TEXT(CBM_20GP,"0.0")&" CBM" -> [████████████████████] 100% · 0.029 / 29 CBM
A37: =IF(AND(B18>=LCL_Breakeven,MOD(B18,CBM_20GP)<24),"DEAD ZONE → EXECUTE TIER-A KNAPSACK TOP-UP","OPTIMAL FILL → BOOK 20' GP FCL AND TRANSMIT PO") -> OPTIMAL FILL → BOOK 20' GP FCL AND TRANSMIT PO
A39: S&OP GOVERNANCE & SIGN-OFF
A40: Prepared by | B40: Supply Chain Analytics · automated control tower | F40: Governance: this workbook is the S&OP sign-off artifact for SOP-OPS-004. It is regenerated deterministically from seed 42. Any manual override must be recorded in the change log and re-validated against the Python quality gate (pytest) before release to the 3PL and factory.
A41: Snapshot date | B41: =Snapshot_Date -> 2026-10-25
A42: S&OP decision | B42: =IF(AND(B11<=5,B12<=5),"APPROVE WEEKLY PLAN","CONDITIONAL APPROVAL - REVIEW EXCEPTIONS") -> CONDITIONAL APPROVAL - REVIEW EXCEPTIONS
A43: Approved by
A44: Approval date

Sheet 01_Catalog_&_Parameters
A1: 01 · CATALOGUE MASTER & GLOBAL POLICY PARAMETERS
A2: Snapshot 2026-10-25 · 160 child FNSKUs · 6 product families · all downstream formulas reference these control cells
A3: Nivel 1 mean lead time (3PL → FBA), days | B3: 14 | D3: Credibility kappa (James-Stein) | F3: 7
A4: Nivel 1 lead-time std deviation, days | B4: 3 | D4: Substitution spillover gamma | F4: 0.1
A5: Nivel 2 mean lead time (Factory → 3PL), days | B5: 75 | D5: Low-inventory HDoS threshold, days | F5: 28
A6: Nivel 2 lead-time std deviation, days | B6: 10 | D6: Fee exemption weekly unit floor | F6: 20
A7: Low-inventory fee shield, days | B7: 32 | D7: FBA removal fee per unit, USD | F7: 0.84
A8: FBA transfer review cycle, days | B8: 21 | D8: AIS removal payback hurdle, months | F8: 12
A9: FBA age-safe cap after transfer, days | B9: 120 | D9: Aggregate PO MOQ, units | F9: 5000
A10: 20' GP usable capacity, CBM | B10: 28.8 | D10: LCL / FCL breakeven, CBM | F10: 15
A11: 40' HC usable capacity, CBM | B11: 70 | D11: Tier-A top-up reserve, CBM | F11: 1.8
A12: System DOS cap for base + top-up, days | B12: 135 | D12: Hero weekly velocity floor, units | F12: 20
A13: Snapshot date | B13: 2026-10-25 | D13: Blue cells are policy controls. Change a value here and every tab recalculates. The catalogue table below is the single source of truth for carton physics, MOQs and unit volume.
A15: sku_id | B15: parent_sku_id | C15: asin | D15: fnsku | E15: shopify_variant_id | F15: material | G15: size_width | H15: color | I15: hardware | J15: abc_xyz_tier | K15: z_score | L15: master_carton_qty | M15: carton_volume_cbm | N15: carton_weight_kg | O15: sku_moq_units | P15: po_aggregate_moq_units | Q15: fob_unit_cost | R15: landed_cost | S15: retail_price | T15: parent_stationary_share | U15: unit_volume_cuft | V15: fba_channel_share | W15: fba_size_tier | X15: supplier_id
A16: P01-RPN-S-BLK-ZIP | B16: P01-PCK-CUBE | C16: B03SNEEV2P | D16: X002059777 | E16: 4400000000000 | F16: 20D Ripstop Nylon | G16: S | H16: Black | I16: Standard Zip | J16: AY | K16: 1.881 | L16: 100 | M16: 0.06 | N16: 12.2 | O16: 300 | P16: 5000 | Q16: 4.2 | R16: 5.15 | S16: 40 | T16: 0.031008 | U16: 0.00564 | V16: 0.72 | W16: Small Standard | X16: SUP-SZ-01
A17: P01-RPN-S-BLK-WRZ | B17: P01-PCK-CUBE | C17: B0SH4UFHC6 | D17: X009764854 | E17: 4400000000001 | F17: 20D Ripstop Nylon | G17: S | H17: Black | I17: Water-Resistant Zip | J17: BY | K17: 1.645 | L17: 100 | M17: 0.06 | N17: 12.2 | O17: 300 | P17: 5000 | Q17: 4.2 | R17: 5.15 | S17: 40 | T17: 0.014592 | U17: 0.00564 | V17: 0.72 | W17: Small Standard | X17: SUP-SZ-01
A18: P01-RPN-S-NVY-ZIP | B18: P01-PCK-CUBE | C18: B0F73JW2VU | D18: X002617730 | E18: 4400000000002 | F18: 20D Ripstop Nylon | G18: S | H18: Navy | I18: Standard Zip | J18: BX | K18: 1.645 | L18: 100 | M18: 0.06 | N18: 12.2 | O18: 300 | P18: 5000 | Q18: 4.2 | R18: 5.15 | S18: 40 | T18: 0.019584 | U18: 0.00564 | V18: 0.72 | W18: Small Standard | X18: SUP-SZ-01
A19: P01-RPN-S-NVY-WRZ | B19: P01-PCK-CUBE | C19: B0ZFWPSR6C | D19: X004405176 | E19: 4400000000003 | F19: 20D Ripstop Nylon | G19: S | H19: Navy | I19: Water-Resistant Zip | J19: CZ | K19: 1.282 | L19: 100 | M19: 0.06 | N19: 12.2 | O19: 300 | P19: 5000 | Q19: 4.2 | R19: 5.15 | S19: 40 | T19: 0.009216 | U19: 0.00564 | V19: 0.72 | W19: Small Standard | X19: SUP-SZ-01
A20: P01-RPN-S-OLV-ZIP | B20: P01-PCK-CUBE | C20: B0XRCYDBWC | D20: X000471416 | E20: 4400000000004 | F20: 20D Ripstop Nylon | G20: S | H20: Olive | I20: Standard Zip | J20: CZ | K20: 1.282 | L20: 100 | M20: 0.06 | N20: 12.2 | O20: 300 | P20: 5000 | Q20: 4.2 | R20: 5.15 | S20: 40 | T20: 0.011424 | U20: 0.00564 | V20: 0.72 | W20: Small Standard | X20: SUP-SZ-01
A21: P01-RPN-S-OLV-WRZ | B21: P01-PCK-CUBE | C21: B0GB7KNXE5 | D21: X008670378 | E21: 4400000000005 | F21: 20D Ripstop Nylon | G21: S | H21: Olive | I21: Water-Resistant Zip | J21: CZ | K21: 1.282 | L21: 100 | M21: 0.06 | N21: 12.2 | O21: 300 | P21: 5000 | Q21: 4.2 | R21: 5.15 | S21: 40 | T21: 0.005376 | U21: 0.00564 | V21: 0.72 | W21: Small Standard | X21: SUP-SZ-01
A22: P01-RPN-S-SLT-ZIP | B22: P01-PCK-CUBE | C22: B0ETUDW98P | D22: X006181807 | E22: 4400000000006 | F22: 20D Ripstop Nylon | G22: S | H22: Slate | I22: Standard Zip | J22: CZ | K22: 1.282 | L22: 100 | M22: 0.06 | N22: 12.2 | O22: 300 | P22: 5000 | Q22: 4.2 | R22: 5.15 | S22: 40 | T22: 0.008976 | U22: 0.00564 | V22: 0.72 | W22: Small Standard | X22: SUP-SZ-01
A23: P01-RPN-S-SLT-WRZ | B23: P01-PCK-CUBE | C23: B0SSNGP9SJ | D23: X004550121 | E23: 4400000000007 | F23: 20D Ripstop Nylon | G23: S | H23: Slate | I23: Water-Resistant Zip | J23: CZ | K23: 1.282 | L23: 100 | M23: 0.06 | N23: 12.2 | O23: 300 | P23: 5000 | Q23: 4.2 | R23: 5.15 | S23: 40 | T23: 0.004224 | U23: 0.00564 | V23: 0.72 | W23: Small Standard | X23: SUP-SZ-01
A24: P01-RPN-S-SND-ZIP | B24: P01-PCK-CUBE | C24: B0ENNGVK2S | D24: X005655057 | E24: 4400000000008 | F24: 20D Ripstop Nylon | G24: S | H24: Sand | I24: Standard Zip | J24: CZ | K24: 1.282 | L24: 100 | M24: 0.06 | N24: 12.2 | O24: 300 | P24: 5000 | Q24: 4.2 | R24: 5.15 | S24: 40 | T24: 0.006528 | U24: 0.00564 | V24: 0.72 | W24: Small Standard | X24: SUP-SZ-01
A25: P01-RPN-S-SND-WRZ | B25: P01-PCK-CUBE | C25: B0AL1BEZ79 | D25: X004980280 | E25: 4400000000009 | F25: 20D Ripstop Nylon | G25: S | H25: Sand | I25: Water-Resistant Zip | J25: CZ | K25: 1.282 | L25: 100 | M25: 0.06 | N25: 12.2 | O25: 300 | P25: 5000 | Q25: 4.2 | R25: 5.15 | S25: 40 | T25: 0.003072 | U25: 0.00564 | V25: 0.72 | W25: Small Standard | X25: SUP-SZ-01
A26: P01-RPN-S-TRC-ZIP | B26: P01-PCK-CUBE | C26: B0V9X9EN4J | D26: X005796444 | E26: 4400000000010 | F26: 20D Ripstop Nylon | G26: S | H26: Terracotta | I26: Standard Zip | J26: CZ | K26: 1.282 | L26: 100 | M26: 0.06 | N26: 12.2 | O26: 300 | P26: 5000 | Q26: 4.2 | R26: 5.15 | S26: 40 | T26: 0.00408 | U26: 0.00564 | V26: 0.72 | W26: Small Standard | X26: SUP-SZ-01
A27: P01-RPN-S-TRC-WRZ | B27: P01-PCK-CUBE | C27: B0TA5B033S | D27: X007647195 | E27: 4400000000011 | F27: 20D Ripstop Nylon | G27: S | H27: Terracotta | I27: Water-Resistant Zip | J27: CZ | K27: 1.282 | L27: 100 | M27: 0.06 | N27: 12.2 | O27: 300 | P27: 5000 | Q27: 4.2 | R27: 5.15 | S27: 40 | T27: 0.00192 | U27: 0.00564 | V27: 0.72 | W27: Small Standard | X27: SUP-SZ-01
... A175: P06-MSH-L-SND-DST | B175: P06-LAU-BAG | C175: B0VYZYVF6L | D175: X002469227 | E175: 4400000000159 | F175: Recycled Poly Mesh | G175: L | H175: Sand | I175: Drawstring | J175: CZ | K175: 1.282 | L175: 50 | M175: 0.084 | N175: 12.5 | O175: 500 | P175: 5000 | Q175: 9.4 | R175: 11.2 | S175: 65 | T175: 0.02963 | U175: 0.011 | V175: 0.45 | W175: Small Standard | X175: SUP-NB-03

Sheet 02_Demand_Unconstraining
A1: 02 · DEMAND UNCONSTRAINING · CENSORED → LATENT VELOCITY
A2: Recovery ladder: active-day exposure τ · sister-SKU imputation with γ=10% · 90-day and lifetime fallbacks. K takes H when τ>0, else Y, else J. The κ=7 blend is a rejected diagnostic, not the shipped rule. Red rows have <20 active days in the 30-day window.
A4: sku_id | B4: parent_sku_id | C4: tier | D4: FBA share | E4: FBA sales 30d | F4: Active days 30d | G4: Naive 30d u/d | H4: Active-day u/d | I4: 90d baseline u/d | J4: Cross-sectional u/d | K4: D_FBA unconstrained | L4: σ_FBA | M4: DTC sales 30d | N4: DTC active days | O4: DTC naive u/d | P4: DTC active u/d | Q4: D_DTC unconstrained | R4: D_Global unconstrained | S4: σ_Global | T4: Stockout ratio | U4: Unconstraining uplift | V4: Exposure ratio | W4: Stockout days 30d | X4: Alert | Y4: Fallback pool u/d
A5: P01-RPN-S-BLK-ZIP | B5: P01-PCK-CUBE | C5: AY | D5: 0.72 | E5: 422 | F5: 30 | G5: =E5/30 -> 14.066667 | H5: 14.0667 | I5: 12.6889 | J5: 14.0667 | K5: 14.0667 | L5: 5.6835 | M5: 60 | N5: 11.2928 | O5: =M5/30 -> 2 | P5: 5.3131 | Q5: 5.3131 | R5: 19.3798 | S5: 6.1659 | T5: =MAX(0,(30-F5)/30) -> 0 | U5: =IF(G5>0,K5/G5-1,0) -> 2.3696682e-06 | V5: =F5/30 -> 1 | W5: =MAX(0,30-F5) -> 0 | X5: =IF(F5<20,"CENSORED - REVIEW ACTIVE DAY","OK") -> OK | Y5: 12.6889
A6: P01-RPN-S-BLK-WRZ | B6: P01-PCK-CUBE | C6: BY | D6: 0.72 | E6: 32 | F6: 30 | G6: =E6/30 -> 1.0666667 | H6: 1.0667 | I6: 1.1444 | J6: 1.0667 | K6: 1.0667 | L6: 0.7253 | M6: 18 | N6: 30 | O6: =M6/30 -> 0.6 | P6: 0.6 | Q6: 0.6 | R6: 1.6667 | S6: 0.8322 | T6: =MAX(0,(30-F6)/30) -> 0 | U6: =IF(G6>0,K6/G6-1,0) -> 3.125e-05 | V6: =F6/30 -> 1 | W6: =MAX(0,30-F6) -> 0 | X6: =IF(F6<20,"CENSORED - REVIEW ACTIVE DAY","OK") -> OK | Y6: 1.1444
A7: P01-RPN-S-NVY-ZIP | B7: P01-PCK-CUBE | C7: BX | D7: 0.72 | E7: 26 | F7: 11.3551 | G7: =E7/30 -> 0.86666667 | H7: 2.2897 | I7: 2.2283 | J7: 7.2846 | K7: 2.2897 | L7: 1.1449 | M7: 39 | N7: 30 | O7: =M7/30 -> 1.3 | P7: 1.3 | Q7: 1.3 | R7: 3.5897 | S7: 1.3165 | T7: =MAX(0,(30-F7)/30) -> 0.62149667 | U7: =IF(G7>0,K7/G7-1,0) -> 1.6419615 | V7: =F7/30 -> 0.37850333 | W7: =MAX(0,30-F7) -> 18.6449 | X7: =IF(F7<20,"CENSORED - REVIEW ACTIVE DAY","OK") -> CENSORED - REVIEW ACTIVE DAY | Y7: 2.2283
A8: P01-RPN-S-NVY-WRZ | B8: P01-PCK-CUBE | C8: CZ | D8: 0.72 | E8: 0 | F8: 0 | G8: =E8/30 -> 0 | H8: 0 | I8: 0 | J8: 3.3127 | K8: 0.6849 | L8: 0.4452 | M8: 8 | N8: 30 | O8: =M8/30 -> 0.26666667 | P8: 0.2667 | Q8: 0.2667 | R8: 0.9516 | S8: 0.5725 | T8: =MAX(0,(30-F8)/30) -> 1 | U8: =IF(G8>0,K8/G8-1,0) -> 0 | V8: =F8/30 -> 0 | W8: =MAX(0,30-F8) -> 30 | X8: =IF(F8<20,"CENSORED - REVIEW ACTIVE DAY","OK") -> CENSORED - REVIEW ACTIVE DAY | Y8: 0.6849
A9: P01-RPN-S-OLV-ZIP | B9: P01-PCK-CUBE | C9: CZ | D9: 0.72 | E9: 0 | F9: 0 | G9: =E9/30 -> 0 | H9: 0 | I9: 0 | J9: 4.1064 | K9: 0.6851 | L9: 0.4453 | M9: 7 | N9: 30 | O9: =M9/30 -> 0.23333333 | P9: 0.2333 | Q9: 0.2333 | R9: 0.9184 | S9: 0.5455 | T9: =MAX(0,(30-F9)/30) -> 1 | U9: =IF(G9>0,K9/G9-1,0) -> 0 | V9: =F9/30 -> 0 | W9: =MAX(0,30-F9) -> 30 | X9: =IF(F9<20,"CENSORED - REVIEW ACTIVE DAY","OK") -> CENSORED - REVIEW ACTIVE DAY | Y9: 0.6851
A10: P01-RPN-S-OLV-WRZ | B10: P01-PCK-CUBE | C10: CZ | D10: 0.72 | E10: 11 | F10: 30 | G10: =E10/30 -> 0.36666667 | H10: 0.3667 | I10: 0.4 | J10: 0.3667 | K10: 0.3667 | L10: 0.495 | M10: 4 | N10: 30 | O10: =M10/30 -> 0.13333333 | P10: 0.1333 | Q10: 0.1333 | R10: 0.5 | S10: 0.5267 | T10: =MAX(0,(30-F10)/30) -> 0 | U10: =IF(G10>0,K10/G10-1,0) -> 9.0909091e-05 | V10: =F10/30 -> 1 | W10: =MAX(0,30-F10) -> 0 | X10: =IF(F10<20,"CENSORED - REVIEW ACTIVE DAY","OK") -> OK | Y10: 0.4
A11: P01-RPN-S-SLT-ZIP | B11: P01-PCK-CUBE | C11: CZ | D11: 0.72 | E11: 0 | F11: 0 | G11: =E11/30 -> 0 | H11: 0 | I11: 0 | J11: 3.2264 | K11: 0.719 | L11: 0.4674 | M11: 3 | N11: 30 | O11: =M11/30 -> 0.1 | P11: 0.1 | Q11: 0.1 | R11: 0.819 | S11: 0.4865 | T11: =MAX(0,(30-F11)/30) -> 1 | U11: =IF(G11>0,K11/G11-1,0) -> 0 | V11: =F11/30 -> 0 | W11: =MAX(0,30-F11) -> 30 | X11: =IF(F11<20,"CENSORED - REVIEW ACTIVE DAY","OK") -> CENSORED - REVIEW ACTIVE DAY | Y11: 0.719
A12: P01-RPN-S-SLT-WRZ | B12: P01-PCK-CUBE | C12: CZ | D12: 0.72 | E12: 0 | F12: 0 | G12: =E12/30 -> 0 | H12: 0 | I12: 0 | J12: 1.5183 | K12: 0.2836 | L12: 0.1843 | M12: 0 | N12: 30 | O12: =M12/30 -> 0 | P12: 0 | Q12: 0 | R12: 0.2836 | S12: 0.1843 | T12: =MAX(0,(30-F12)/30) -> 1 | U12: =IF(G12>0,K12/G12-1,0) -> 0 | V12: =F12/30 -> 0 | W12: =MAX(0,30-F12) -> 30 | X12: =IF(F12<20,"CENSORED - REVIEW ACTIVE DAY","OK") -> CENSORED - REVIEW ACTIVE DAY | Y12: 0.2836
A13: P01-RPN-S-SND-ZIP | B13: P01-PCK-CUBE | C13: CZ | D13: 0.72 | E13: 0 | F13: 0 | G13: =E13/30 -> 0 | H13: 0 | I13: 0 | J13: 2.3465 | K13: 0.515 | L13: 0.3348 | M13: 3 | N13: 30 | O13: =M13/30 -> 0.1 | P13: 0.1 | Q13: 0.1 | R13: 0.615 | S13: 0.361 | T13: =MAX(0,(30-F13)/30) -> 1 | U13: =IF(G13>0,K13/G13-1,0) -> 0 | V13: =F13/30 -> 0 | W13: =MAX(0,30-F13) -> 30 | X13: =IF(F13<20,"CENSORED - REVIEW ACTIVE DAY","OK") -> CENSORED - REVIEW ACTIVE DAY | Y13: 0.515
A14: P01-RPN-S-SND-WRZ | B14: P01-PCK-CUBE | C14: CZ | D14: 0.72 | E14: 0 | F14: 0 | G14: =E14/30 -> 0 | H14: 0 | I14: 0 | J14: 1.1042 | K14: 0.1791 | L14: 0.1164 | M14: 0 | N14: 30 | O14: =M14/30 -> 0 | P14: 0 | Q14: 0 | R14: 0.1791 | S14: 0.1164 | T14: =MAX(0,(30-F14)/30) -> 1 | U14: =IF(G14>0,K14/G14-1,0) -> 0 | V14: =F14/30 -> 0 | W14: =MAX(0,30-F14) -> 30 | X14: =IF(F14<20,"CENSORED - REVIEW ACTIVE DAY","OK") -> CENSORED - REVIEW ACTIVE DAY | Y14: 0.1791
A15: P01-RPN-S-TRC-ZIP | B15: P01-PCK-CUBE | C15: CZ | D15: 0.72 | E15: 8 | F15: 30 | G15: =E15/30 -> 0.26666667 | H15: 0.2667 | I15: 0.2222 | J15: 0.2667 | K15: 0.2667 | L15: 0.36 | M15: 4 | N15: 30 | O15: =M15/30 -> 0.13333333 | P15: 0.1333 | Q15: 0.1333 | R15: 0.4 | S15: 0.4025 | T15: =MAX(0,(30-F15)/30) -> 0 | U15: =IF(G15>0,K15/G15-1,0) -> 0.000125 | V15: =F15/30 -> 1 | W15: =MAX(0,30-F15) -> 0 | X15: =IF(F15<20,"CENSORED - REVIEW ACTIVE DAY","OK") -> OK | Y15: 0.2222
A16: P01-RPN-S-TRC-WRZ | B16: P01-PCK-CUBE | C16: CZ | D16: 0.72 | E16: 0 | F16: 0 | G16: =E16/30 -> 0 | H16: 0 | I16: 0 | J16: 0.6901 | K16: 0.115 | L16: 0.0748 | M16: 1 | N16: 30 | O16: =M16/30 -> 0.033333333 | P16: 0.0333 | Q16: 0.0333 | R16: 0.1483 | S16: 0.0873 | T16: =MAX(0,(30-F16)/30) -> 1 | U16: =IF(G16>0,K16/G16-1,0) -> 0 | V16: =F16/30 -> 0 | W16: =MAX(0,30-F16) -> 30 | X16: =IF(F16<20,"CENSORED - REVIEW ACTIVE DAY","OK") -> CENSORED - REVIEW ACTIVE DAY | Y16: 0.115
... A164: P06-MSH-L-SND-DST | B164: P06-LAU-BAG | C164: CZ | D164: 0.45 | E164: 30 | F164: 30 | G164: =E164/30 -> 1 | H164: 1 | I164: 1.0667 | J164: 1 | K164: 1 | L164: 1.35 | M164: 29 | N164: 30 | O164: =M164/30 -> 0.96666667 | P164: 0.9667 | Q164: 0.9667 | R164: 1.9667 | S164: 1.8776 | T164: =MAX(0,(30-F164)/30) -> 0 | U164: =IF(G164>0,K164/G164-1,0) -> 0 | V164: =F164/30 -> 1 | W164: =MAX(0,30-F164) -> 0 | X164: =IF(F164<20,"CENSORED - REVIEW ACTIVE DAY","OK") -> OK | Y164: 1.0667

Sheet 03_FBA_Nivel1_Transfer
A1: 03 · FBA NIVEL 1 · 3PL → FBA TRANSFER & FEE SHIELD
A2: Effective HDoS = MAX(30d, 90d). B_FBA = MAX(SS1, 32·D_FBA) for non-exempt heroes. Transfers are age-safe master-carton multiples (120-day cap).
A4: sku_id | B4: parent_sku_id | C4: tier | D4: FBA available | E4: IP_FBA | F4: HDoS 30d | G4: HDoS 90d | H4: Effective HDoS | I4: Fee / unit | J4: Fee exempt | K4: D_FBA u/d | L4: σ_FBA | M4: SS1 | N4: B_FBA shield | O4: ROP1 | P4: S_max1 | Q4: 3PL cartons avail | R4: Age-safe cartons | S4: Transfer units | T4: Transfer cartons | U4: FC transfer | V4: Inbound shipped | W4: Inbound receiving | X4: Transfer CBM | Y4: Post-transfer DOS | Z4: Fee exposure | AA4: Alert | AB4: Carton check
A5: P01-RPN-S-BLK-ZIP | B5: P01-PCK-CUBE | C5: AY | D5: 210 | E5: =D5+U5+V5+W5 -> 210 | F5: 29.09 | G5: 34.98 | H5: =MAX(F5,G5) -> 34.98 | I5: 0 | J5: FALSE | K5: 14.0667 | L5: 5.6835 | M5: 88.89 | N5: 451 | O5: 647.93 | P5: 943.33 | Q5: 0 | R5: 8 | S5: =MIN(R5,Q5)*_xlfn.XLOOKUP($A5,tbl_Catalog[sku_id],tbl_Catalog[master_carton_qty]) -> 0 | T5: =IF(_xlfn.XLOOKUP($A5,tbl_Catalog[sku_id],tbl_Catalog[master_carton_qty])>0,S5/_xlfn.XLOOKUP($A5,tbl_Catalog[sku_id],tbl_Catalog[master_carton_qty]),0) -> 0 | U5: 0 | V5: 0 | W5: 0 | X5: =T5*_xlfn.XLOOKUP($A5,tbl_Catalog[sku_id],tbl_Catalog[carton_volume_cbm]) -> 0 | Y5: =IF(K5>0,(E5+S5)/K5,0) -> 14.928875 | Z5: =S5*I5 -> 0 | AA5: =IF(AND(H5<Fee_Threshold,I5>0),"LOW-INVENTORY FEE ACTIVE",IF(H5<Fee_Threshold,"EXEMPT / AUDIT","SHIELDED")) -> SHIELDED | AB5: =IF(MOD(S5,_xlfn.XLOOKUP($A5,tbl_Catalog[sku_id],tbl_Catalog[master_carton_qty]))=0,"CARTON OK","CHECK") -> CARTON OK
A6: P01-RPN-S-BLK-WRZ | B6: P01-PCK-CUBE | C6: BY | D6: 129 | E6: =D6+U6+V6+W6 -> 129 | F6: 68 | G6: 61.06 | H6: =MAX(F6,G6) -> 68 | I6: 0 | J6: TRUE | K6: 1.0667 | L6: 0.7253 | M6: 6.9 | N6: 7 | O6: 21.93 | P6: 44.33 | Q6: 0 | R6: 0 | S6: =MIN(R6,Q6)*_xlfn.XLOOKUP($A6,tbl_Catalog[sku_id],tbl_Catalog[master_carton_qty]) -> 0 | T6: =IF(_xlfn.XLOOKUP($A6,tbl_Catalog[sku_id],tbl_Catalog[master_carton_qty])>0,S6/_xlfn.XLOOKUP($A6,tbl_Catalog[sku_id],tbl_Catalog[master_carton_qty]),0) -> 0 | U6: 0 | V6: 0 | W6: 0 | X6: =T6*_xlfn.XLOOKUP($A6,tbl_Catalog[sku_id],tbl_Catalog[carton_volume_cbm]) -> 0 | Y6: =IF(K6>0,(E6+S6)/K6,0) -> 120.93372 | Z6: =S6*I6 -> 0 | AA6: =IF(AND(H6<Fee_Threshold,I6>0),"LOW-INVENTORY FEE ACTIVE",IF(H6<Fee_Threshold,"EXEMPT / AUDIT","SHIELDED")) -> SHIELDED | AB6: =IF(MOD(S6,_xlfn.XLOOKUP($A6,tbl_Catalog[sku_id],tbl_Catalog[master_carton_qty]))=0,"CARTON OK","CHECK") -> CARTON OK
A7: P01-RPN-S-NVY-ZIP | B7: P01-PCK-CUBE | C7: BX | D7: 0 | E7: =D7+U7+V7+W7 -> 0 | F7: 5.69 | G7: 36.1 | H7: =MAX(F7,G7) -> 36.1 | I7: 0 | J7: TRUE | K7: 2.2897 | L7: 1.1449 | M7: 13.32 | N7: 14 | O7: 46.06 | P7: 94.14 | Q7: 0 | R7: 1 | S7: =MIN(R7,Q7)*_xlfn.XLOOKUP($A7,tbl_Catalog[sku_id],tbl_Catalog[master_carton_qty]) -> 0 | T7: =IF(_xlfn.XLOOKUP($A7,tbl_Catalog[sku_id],tbl_Catalog[master_carton_qty])>0,S7/_xlfn.XLOOKUP($A7,tbl_Catalog[sku_id],tbl_Catalog[master_carton_qty]),0) -> 0 | U7: 0 | V7: 0 | W7: 0 | X7: =T7*_xlfn.XLOOKUP($A7,tbl_Catalog[sku_id],tbl_Catalog[carton_volume_cbm]) -> 0 | Y7: =IF(K7>0,(E7+S7)/K7,0) -> 0 | Z7: =S7*I7 -> 0 | AA7: =IF(AND(H7<Fee_Threshold,I7>0),"LOW-INVENTORY FEE ACTIVE",IF(H7<Fee_Threshold,"EXEMPT / AUDIT","SHIELDED")) -> SHIELDED | AB7: =IF(MOD(S7,_xlfn.XLOOKUP($A7,tbl_Catalog[sku_id],tbl_Catalog[master_carton_qty]))=0,"CARTON OK","CHECK") -> CARTON OK
A8: P01-RPN-S-NVY-WRZ | B8: P01-PCK-CUBE | C8: CZ | D8: 0 | E8: =D8+U8+V8+W8 -> 0 | F8: 0 | G8: 0 | H8: =MAX(F8,G8) -> 0 | I8: 0 | J8: TRUE | K8: 0.6849 | L8: 0.4452 | M8: 3.39 | N8: 4 | O8: 13.59 | P8: 27.97 | Q8: 3 | R8: 0 | S8: =MIN(R8,Q8)*_xlfn.XLOOKUP($A8,tbl_Catalog[sku_id],tbl_Catalog[master_carton_qty]) -> 0 | T8: =IF(_xlfn.XLOOKUP($A8,tbl_Catalog[sku_id],tbl_Catalog[master_carton_qty])>0,S8/_xlfn.XLOOKUP($A8,tbl_Catalog[sku_id],tbl_Catalog[master_carton_qty]),0) -> 0 | U8: 0 | V8: 0 | W8: 0 | X8: =T8*_xlfn.XLOOKUP($A8,tbl_Catalog[sku_id],tbl_Catalog[carton_volume_cbm]) -> 0 | Y8: =IF(K8>0,(E8+S8)/K8,0) -> 0 | Z8: =S8*I8 -> 0 | AA8: =IF(AND(H8<Fee_Threshold,I8>0),"LOW-INVENTORY FEE ACTIVE",IF(H8<Fee_Threshold,"EXEMPT / AUDIT","SHIELDED")) -> EXEMPT / AUDIT | AB8: =IF(MOD(S8,_xlfn.XLOOKUP($A8,tbl_Catalog[sku_id],tbl_Catalog[master_carton_qty]))=0,"CARTON OK","CHECK") -> CARTON OK
A9: P01-RPN-S-OLV-ZIP | B9: P01-PCK-CUBE | C9: CZ | D9: 0 | E9: =D9+U9+V9+W9 -> 0 | F9: 0 | G9: 0 | H9: =MAX(F9,G9) -> 0 | I9: 0 | J9: TRUE | K9: 0.6851 | L9: 0.4453 | M9: 3.39 | N9: 4 | O9: 13.59 | P9: 27.98 | Q9: 2 | R9: 0 | S9: =MIN(R9,Q9)*_xlfn.XLOOKUP($A9,tbl_Catalog[sku_id],tbl_Catalog[master_carton_qty]) -> 0 | T9: =IF(_xlfn.XLOOKUP($A9,tbl_Catalog[sku_id],tbl_Catalog[master_carton_qty])>0,S9/_xlfn.XLOOKUP($A9,tbl_Catalog[sku_id],tbl_Catalog[master_carton_qty]),0) -> 0 | U9: 0 | V9: 0 | W9: 0 | X9: =T9*_xlfn.XLOOKUP($A9,tbl_Catalog[sku_id],tbl_Catalog[carton_volume_cbm]) -> 0 | Y9: =IF(K9>0,(E9+S9)/K9,0) -> 0 | Z9: =S9*I9 -> 0 | AA9: =IF(AND(H9<Fee_Threshold,I9>0),"LOW-INVENTORY FEE ACTIVE",IF(H9<Fee_Threshold,"EXEMPT / AUDIT","SHIELDED")) -> EXEMPT / AUDIT | AB9: =IF(MOD(S9,_xlfn.XLOOKUP($A9,tbl_Catalog[sku_id],tbl_Catalog[master_carton_qty]))=0,"CARTON OK","CHECK") -> CARTON OK
A10: P01-RPN-S-OLV-WRZ | B10: P01-PCK-CUBE | C10: CZ | D10: 87 | E10: =D10+U10+V10+W10 -> 87 | F10: 251.18 | G10: 257.36 | H10: =MAX(F10,G10) -> 257.36 | I10: 0 | J10: TRUE | K10: 0.3667 | L10: 0.495 | M10: 2.76 | N10: 3 | O10: 8.13 | P10: 15.83 | Q10: 1 | R10: 0 | S10: =MIN(R10,Q10)*_xlfn.XLOOKUP($A10,tbl_Catalog[sku_id],tbl_Catalog[master_carton_qty]) -> 0 | T10: =IF(_xlfn.XLOOKUP($A10,tbl_Catalog[sku_id],tbl_Catalog[master_carton_qty])>0,S10/_xlfn.XLOOKUP($A10,tbl_Catalog[sku_id],tbl_Catalog[master_carton_qty]),0) -> 0 | U10: 0 | V10: 0 | W10: 0 | X10: =T10*_xlfn.XLOOKUP($A10,tbl_Catalog[sku_id],tbl_Catalog[carton_volume_cbm]) -> 0 | Y10: =IF(K10>0,(E10+S10)/K10,0) -> 237.25116 | Z10: =S10*I10 -> 0 | AA10: =IF(AND(H10<Fee_Threshold,I10>0),"LOW-INVENTORY FEE ACTIVE",IF(H10<Fee_Threshold,"EXEMPT / AUDIT","SHIELDED")) -> SHIELDED | AB10: =IF(MOD(S10,_xlfn.XLOOKUP($A10,tbl_Catalog[sku_id],tbl_Catalog[master_carton_qty]))=0,"CARTON OK","CHECK") -> CARTON OK
A11: P01-RPN-S-SLT-ZIP | B11: P01-PCK-CUBE | C11: CZ | D11: 0 | E11: =D11+U11+V11+W11 -> 0 | F11: 0 | G11: 0 | H11: =MAX(F11,G11) -> 0 | I11: 0 | J11: TRUE | K11: 0.719 | L11: 0.4674 | M11: 3.56 | N11: 4 | O11: 14.07 | P11: 29.16 | Q11: 3 | R11: 0 | S11: =MIN(R11,Q11)*_xlfn.XLOOKUP($A11,tbl_Catalog[sku_id],tbl_Catalog[master_carton_qty]) -> 0 | T11: =IF(_xlfn.XLOOKUP($A11,tbl_Catalog[sku_id],tbl_Catalog[master_carton_qty])>0,S11/_xlfn.XLOOKUP($A11,tbl_Catalog[sku_id],tbl_Catalog[master_carton_qty]),0) -> 0 | U11: 0 | V11: 0 | W11: 0 | X11: =T11*_xlfn.XLOOKUP($A11,tbl_Catalog[sku_id],tbl_Catalog[carton_volume_cbm]) -> 0 | Y11: =IF(K11>0,(E11+S11)/K11,0) -> 0 | Z11: =S11*I11 -> 0 | AA11: =IF(AND(H11<Fee_Threshold,I11>0),"LOW-INVENTORY FEE ACTIVE",IF(H11<Fee_Threshold,"EXEMPT / AUDIT","SHIELDED")) -> EXEMPT / AUDIT | AB11: =IF(MOD(S11,_xlfn.XLOOKUP($A11,tbl_Catalog[sku_id],tbl_Catalog[master_carton_qty]))=0,"CARTON OK","CHECK") -> CARTON OK
A12: P01-RPN-S-SLT-WRZ | B12: P01-PCK-CUBE | C12: CZ | D12: 0 | E12: =D12+U12+V12+W12 -> 0 | F12: 0 | G12: 0 | H12: =MAX(F12,G12) -> 0 | I12: 0 | J12: TRUE | K12: 0.2836 | L12: 0.1843 | M12: 1.4 | N12: 2 | O12: 5.97 | P12: 11.93 | Q12: 2 | R12: 0 | S12: =MIN(R12,Q12)*_xlfn.XLOOKUP($A12,tbl_Catalog[sku_id],tbl_Catalog[master_carton_qty]) -> 0 | T12: =IF(_xlfn.XLOOKUP($A12,tbl_Catalog[sku_id],tbl_Catalog[master_carton_qty])>0,S12/_xlfn.XLOOKUP($A12,tbl_Catalog[sku_id],tbl_Catalog[master_carton_qty]),0) -> 0 | U12: 0 | V12: 0 | W12: 0 | X12: =T12*_xlfn.XLOOKUP($A12,tbl_Catalog[sku_id],tbl_Catalog[carton_volume_cbm]) -> 0 | Y12: =IF(K12>0,(E12+S12)/K12,0) -> 0 | Z12: =S12*I12 -> 0 | AA12: =IF(AND(H12<Fee_Threshold,I12>0),"LOW-INVENTORY FEE ACTIVE",IF(H12<Fee_Threshold,"EXEMPT / AUDIT","SHIELDED")) -> EXEMPT / AUDIT | AB12: =IF(MOD(S12,_xlfn.XLOOKUP($A12,tbl_Catalog[sku_id],tbl_Catalog[master_carton_qty]))=0,"CARTON OK","CHECK") -> CARTON OK
A13: P01-RPN-S-SND-ZIP | B13: P01-PCK-CUBE | C13: CZ | D13: 0 | E13: =D13+U13+V13+W13 -> 0 | F13: 0 | G13: 0 | H13: =MAX(F13,G13) -> 0 | I13: 0 | J13: TRUE | K13: 0.515 | L13: 0.3348 | M13: 2.55 | N13: 3 | O13: 10.21 | P13: 21.02 | Q13: 3 | R13: 0 | S13: =MIN(R13,Q13)*_xlfn.XLOOKUP($A13,tbl_Catalog[sku_id],tbl_Catalog[master_carton_qty]) -> 0 | T13: =IF(_xlfn.XLOOKUP($A13,tbl_Catalog[sku_id],tbl_Catalog[master_carton_qty])>0,S13/_xlfn.XLOOKUP($A13,tbl_Catalog[sku_id],tbl_Catalog[master_carton_qty]),0) -> 0 | U13: 0 | V13: 0 | W13: 0 | X13: =T13*_xlfn.XLOOKUP($A13,tbl_Catalog[sku_id],tbl_Catalog[carton_volume_cbm]) -> 0 | Y13: =IF(K13>0,(E13+S13)/K13,0) -> 0 | Z13: =S13*I13 -> 0 | AA13: =IF(AND(H13<Fee_Threshold,I13>0),"LOW-INVENTORY FEE ACTIVE",IF(H13<Fee_Threshold,"EXEMPT / AUDIT","SHIELDED")) -> EXEMPT / AUDIT | AB13: =IF(MOD(S13,_xlfn.XLOOKUP($A13,tbl_Catalog[sku_id],tbl_Catalog[master_carton_qty]))=0,"CARTON OK","CHECK") -> CARTON OK
A14: P01-RPN-S-SND-WRZ | B14: P01-PCK-CUBE | C14: CZ | D14: 0 | E14: =D14+U14+V14+W14 -> 0 | F14: 0 | G14: 0 | H14: =MAX(F14,G14) -> 0 | I14: 0 | J14: TRUE | K14: 0.1791 | L14: 0.1164 | M14: 0.89 | N14: 1 | O14: 3.51 | P14: 7.27 | Q14: 3 | R14: 0 | S14: =MIN(R14,Q14)*_xlfn.XLOOKUP($A14,tbl_Catalog[sku_id],tbl_Catalog[master_carton_qty]) -> 0 | T14: =IF(_xlfn.XLOOKUP($A14,tbl_Catalog[sku_id],tbl_Catalog[master_carton_qty])>0,S14/_xlfn.XLOOKUP($A14,tbl_Catalog[sku_id],tbl_Catalog[master_carton_qty]),0) -> 0 | U14: 0 | V14: 0 | W14: 0 | X14: =T14*_xlfn.XLOOKUP($A14,tbl_Catalog[sku_id],tbl_Catalog[carton_volume_cbm]) -> 0 | Y14: =IF(K14>0,(E14+S14)/K14,0) -> 0 | Z14: =S14*I14 -> 0 | AA14: =IF(AND(H14<Fee_Threshold,I14>0),"LOW-INVENTORY FEE ACTIVE",IF(H14<Fee_Threshold,"EXEMPT / AUDIT","SHIELDED")) -> EXEMPT / AUDIT | AB14: =IF(MOD(S14,_xlfn.XLOOKUP($A14,tbl_Catalog[sku_id],tbl_Catalog[master_carton_qty]))=0,"CARTON OK","CHECK") -> CARTON OK
A15: P01-RPN-S-TRC-ZIP | B15: P01-PCK-CUBE | C15: CZ | D15: 125 | E15: =D15+U15+V15+W15 -> 125 | F15: 483.88 | G15: 607.8 | H15: =MAX(F15,G15) -> 607.8 | I15: 0 | J15: TRUE | K15: 0.2667 | L15: 0.36 | M15: 2.01 | N15: 3 | O15: 6.73 | P15: 12.33 | Q15: 0 | R15: 0 | S15: =MIN(R15,Q15)*_xlfn.XLOOKUP($A15,tbl_Catalog[sku_id],tbl_Catalog[master_carton_qty]) -> 0 | T15: =IF(_xlfn.XLOOKUP($A15,tbl_Catalog[sku_id],tbl_Catalog[master_carton_qty])>0,S15/_xlfn.XLOOKUP($A15,tbl_Catalog[sku_id],tbl_Catalog[master_carton_qty]),0) -> 0 | U15: 0 | V15: 0 | W15: 0 | X15: =T15*_xlfn.XLOOKUP($A15,tbl_Catalog[sku_id],tbl_Catalog[carton_volume_cbm]) -> 0 | Y15: =IF(K15>0,(E15+S15)/K15,0) -> 468.69141 | Z15: =S15*I15 -> 0 | AA15: =IF(AND(H15<Fee_Threshold,I15>0),"LOW-INVENTORY FEE ACTIVE",IF(H15<Fee_Threshold,"EXEMPT / AUDIT","SHIELDED")) -> SHIELDED | AB15: =IF(MOD(S15,_xlfn.XLOOKUP($A15,tbl_Catalog[sku_id],tbl_Catalog[master_carton_qty]))=0,"CARTON OK","CHECK") -> CARTON OK
A16: P01-RPN-S-TRC-WRZ | B16: P01-PCK-CUBE | C16: CZ | D16: 0 | E16: =D16+U16+V16+W16 -> 0 | F16: 0 | G16: 0 | H16: =MAX(F16,G16) -> 0 | I16: 0 | J16: TRUE | K16: 0.115 | L16: 0.0748 | M16: 0.57 | N16: 1 | O16: 2.61 | P16: 5.03 | Q16: 3 | R16: 0 | S16: =MIN(R16,Q16)*_xlfn.XLOOKUP($A16,tbl_Catalog[sku_id],tbl_Catalog[master_carton_qty]) -> 0 | T16: =IF(_xlfn.XLOOKUP($A16,tbl_Catalog[sku_id],tbl_Catalog[master_carton_qty])>0,S16/_xlfn.XLOOKUP($A16,tbl_Catalog[sku_id],tbl_Catalog[master_carton_qty]),0) -> 0 | U16: 0 | V16: 0 | W16: 0 | X16: =T16*_xlfn.XLOOKUP($A16,tbl_Catalog[sku_id],tbl_Catalog[carton_volume_cbm]) -> 0 | Y16: =IF(K16>0,(E16+S16)/K16,0) -> 0 | Z16: =S16*I16 -> 0 | AA16: =IF(AND(H16<Fee_Threshold,I16>0),"LOW-INVENTORY FEE ACTIVE",IF(H16<Fee_Threshold,"EXEMPT / AUDIT","SHIELDED")) -> EXEMPT / AUDIT | AB16: =IF(MOD(S16,_xlfn.XLOOKUP($A16,tbl_Catalog[sku_id],tbl_Catalog[master_carton_qty]))=0,"CARTON OK","CHECK") -> CARTON OK
... A164: P06-MSH-L-SND-DST | B164: P06-LAU-BAG | C164: CZ | D164: 62 | E164: =D164+U164+V164+W164 -> 62 | F164: 57.63 | G164: 58.14 | H164: =MAX(F164,G164) -> 58.14 | I164: 0 | J164: TRUE | K164: 1 | L164: 1.35 | M164: 7.53 | N164: 8 | O164: 22 | P164: 43 | Q164: 2 | R164: 0 | S164: =MIN(R164,Q164)*_xlfn.XLOOKUP($A164,tbl_Catalog[sku_id],tbl_Catalog[master_carton_qty]) -> 0 | T164: =IF(_xlfn.XLOOKUP($A164,tbl_Catalog[sku_id],tbl_Catalog[master_carton_qty])>0,S164/_xlfn.XLOOKUP($A164,tbl_Catalog[sku_id],tbl_Catalog[master_carton_qty]),0) -> 0 | U164: 0 | V164: 0 | W164: 0 | X164: =T164*_xlfn.XLOOKUP($A164,tbl_Catalog[sku_id],tbl_Catalog[carton_volume_cbm]) -> 0 | Y164: =IF(K164>0,(E164+S164)/K164,0) -> 62 | Z164: =S164*I164 -> 0 | AA164: =IF(AND(H164<Fee_Threshold,I164>0),"LOW-INVENTORY FEE ACTIVE",IF(H164<Fee_Threshold,"EXEMPT / AUDIT","SHIELDED")) -> SHIELDED | AB164: =IF(MOD(S164,_xlfn.XLOOKUP($A164,tbl_Catalog[sku_id],tbl_Catalog[master_carton_qty]))=0,"CARTON OK","CHECK") -> CARTON OK

Sheet 04_Factory_Nivel2_PO_&_CBM
A1: 04 · FACTORY NIVEL 2 · MOQ RECONCILIATION & CONTAINER KNAPSACK
A2: Plan: FCL_20GP · base 26.910 CBM + top-up 1.860 CBM = 28.770 / 28.8 CBM. Base units are container-trimmed; tier-A top-up cartons are the greedy marginal-profit allocation.
A4: sku_id | B4: parent_sku_id | C4: tier | D4: 3PL on hand | E4: Allocated DTC | F4: IP_System | G4: D_Global u/d | H4: σ_Global | I4: Z | J4: SS2 | K4: B_FBA | L4: ROP2 system | M4: S_max2 | N4: MOQ cartons | O4: Days to breach | P4: Executable PO units | Q4: Policy line CBM | R4: Base units | S4: Top-up cartons | T4: Top-up units | U4: Total units | V4: Total cartons | W4: Total CBM | X4: Status | Y4: MOQ check | Z4: DOS check | AA4: Open PO units | AB4: Deferred cartons | AC4: Pulled forward
A5: P01-RPN-S-BLK-ZIP | B5: P01-PCK-CUBE | C5: AY | D5: 0 | E5: 0 | F5: ='03_FBA_Nivel1_Transfer'!E5+D5-E5 -> 210 | G5: ='02_Demand_Unconstraining'!R5 -> 19.3798 | H5: ='02_Demand_Unconstraining'!S5 -> 6.1659 | I5: =_xlfn.XLOOKUP($A5,tbl_Catalog[sku_id],tbl_Catalog[z_score]) -> 1.881 | J5: =ROUNDUP(I5*SQRT(L2_Mean*(H5^2)+(G5^2)*(L2_Std^2)),0) -> 379 | K5: ='03_FBA_Nivel1_Transfer'!N5 -> 451 | L5: =_xlfn.CEILING.MATH(G5*L2_Mean+J5+K5,1) -> 2284 | M5: =_xlfn.CEILING.MATH(G5*(L2_Mean+45)+J5+K5,1) -> 3156 | N5: =_xlfn.CEILING.MATH(_xlfn.XLOOKUP($A5,tbl_Catalog[sku_id],tbl_Catalog[sku_moq_units])/_xlfn.XLOOKUP($A5,tbl_Catalog[sku_id],tbl_Catalog[master_carton_qty]),1) -> 3 | O5: =IF(G5>0,(F5-L5)/G5,999) -> -107.01865 | P5: =_xlfn.LET(_xlpm.ip_sys,$F5,_xlpm.rop_sys,$L5,_xlpm.s_max,$M5,_xlpm.m_qty,_xlfn.XLOOKUP($A5,tbl_Catalog[sku_id],tbl_Catalog[master_carton_qty]),_xlpm.moq,_xlfn.XLOOKUP($A5,tbl_Catalog[sku_id],tbl_Catalog[sku_moq_units]),IF(_xlpm.ip_sys<=_xlpm.rop_sys,_xlfn.CEILING.MATH(MAX(_xlpm.s_max-_xlpm.ip_sys,_xlpm.moq),_xlpm.m_qty),0)) -> 3000 | Q5: =IF(P5>0,(P5/_xlfn.XLOOKUP($A5,tbl_Catalog[sku_id],tbl_Catalog[master_carton_qty]))*_xlfn.XLOOKUP($A5,tbl_Catalog[sku_id],tbl_Catalog[carton_volume_cbm]),0) -> 1.8 | R5: 2400 | S5: 0 | T5: =S5*_xlfn.XLOOKUP($A5,tbl_Catalog[sku_id],tbl_Catalog[master_carton_qty]) -> 0 | U5: =R5+T5 -> 2400 | V5: =IF(_xlfn.XLOOKUP($A5,tbl_Catalog[sku_id],tbl_Catalog[master_carton_qty])>0,U5/_xlfn.XLOOKUP($A5,tbl_Catalog[sku_id],tbl_Catalog[master_carton_qty]),0) -> 24 | W5: =V5*_xlfn.XLOOKUP($A5,tbl_Catalog[sku_id],tbl_Catalog[carton_volume_cbm]) -> 1.44 | X5: =IF(U5=0,"DEFERRED / NO PO",IF(S5>0,"BASE + TIER-A TOP-UP","BASE LOAD")) -> BASE LOAD | Y5: =IF(U5=0,"N/A",IF(AND(MOD(U5,_xlfn.XLOOKUP($A5,tbl_Catalog[sku_id],tbl_Catalog[master_carton_qty]))=0,U5>=_xlfn.XLOOKUP($A5,tbl_Catalog[sku_id],tbl_Catalog[sku_moq_units])),"MOQ OK","CHECK")) -> MOQ OK | Z5: =IF(U5=0,"N/A",IF((F5+U5)/MAX(0.1,G5)<=DOS_Cap,"DOS OK","MOQ OVERRIDE")) -> DOS OK | AA5: 900 | AB5: 0 | AC5: FALSE
A6: P01-RPN-S-BLK-WRZ | B6: P01-PCK-CUBE | C6: BY | D6: 45 | E6: 0 | F6: ='03_FBA_Nivel1_Transfer'!E6+D6-E6 -> 174 | G6: ='02_Demand_Unconstraining'!R6 -> 1.6667 | H6: ='02_Demand_Unconstraining'!S6 -> 0.8322 | I6: =_xlfn.XLOOKUP($A6,tbl_Catalog[sku_id],tbl_Catalog[z_score]) -> 1.645 | J6: =ROUNDUP(I6*SQRT(L2_Mean*(H6^2)+(G6^2)*(L2_Std^2)),0) -> 30 | K6: ='03_FBA_Nivel1_Transfer'!N6 -> 7 | L6: =_xlfn.CEILING.MATH(G6*L2_Mean+J6+K6,1) -> 163 | M6: =_xlfn.CEILING.MATH(G6*(L2_Mean+45)+J6+K6,1) -> 238 | N6: =_xlfn.CEILING.MATH(_xlfn.XLOOKUP($A6,tbl_Catalog[sku_id],tbl_Catalog[sku_moq_units])/_xlfn.XLOOKUP($A6,tbl_Catalog[sku_id],tbl_Catalog[master_carton_qty]),1) -> 3 | O6: =IF(G6>0,(F6-L6)/G6,999) -> 6.599868 | P6: =_xlfn.LET(_xlpm.ip_sys,$F6,_xlpm.rop_sys,$L6,_xlpm.s_max,$M6,_xlpm.m_qty,_xlfn.XLOOKUP($A6,tbl_Catalog[sku_id],tbl_Catalog[master_carton_qty]),_xlpm.moq,_xlfn.XLOOKUP($A6,tbl_Catalog[sku_id],tbl_Catalog[sku_moq_units]),IF(_xlpm.ip_sys<=_xlpm.rop_sys,_xlfn.CEILING.MATH(MAX(_xlpm.s_max-_xlpm.ip_sys,_xlpm.moq),_xlpm.m_qty),0)) -> 0 | Q6: =IF(P6>0,(P6/_xlfn.XLOOKUP($A6,tbl_Catalog[sku_id],tbl_Catalog[master_carton_qty]))*_xlfn.XLOOKUP($A6,tbl_Catalog[sku_id],tbl_Catalog[carton_volume_cbm]),0) -> 0 | R6: 0 | S6: 0 | T6: =S6*_xlfn.XLOOKUP($A6,tbl_Catalog[sku_id],tbl_Catalog[master_carton_qty]) -> 0 | U6: =R6+T6 -> 0 | V6: =IF(_xlfn.XLOOKUP($A6,tbl_Catalog[sku_id],tbl_Catalog[master_carton_qty])>0,U6/_xlfn.XLOOKUP($A6,tbl_Catalog[sku_id],tbl_Catalog[master_carton_qty]),0) -> 0 | W6: =V6*_xlfn.XLOOKUP($A6,tbl_Catalog[sku_id],tbl_Catalog[carton_volume_cbm]) -> 0 | X6: =IF(U6=0,"DEFERRED / NO PO",IF(S6>0,"BASE + TIER-A TOP-UP","BASE LOAD")) -> DEFERRED / NO PO | Y6: =IF(U6=0,"N/A",IF(AND(MOD(U6,_xlfn.XLOOKUP($A6,tbl_Catalog[sku_id],tbl_Catalog[master_carton_qty]))=0,U6>=_xlfn.XLOOKUP($A6,tbl_Catalog[sku_id],tbl_Catalog[sku_moq_units])),"MOQ OK","CHECK")) -> N/A | Z6: =IF(U6=0,"N/A",IF((F6+U6)/MAX(0.1,G6)<=DOS_Cap,"DOS OK","MOQ OVERRIDE")) -> N/A | AA6: 300 | AB6: 0 | AC6: FALSE
A7: P01-RPN-S-NVY-ZIP | B7: P01-PCK-CUBE | C7: BX | D7: 3 | E7: 0 | F7: ='03_FBA_Nivel1_Transfer'!E7+D7-E7 -> 3 | G7: ='02_Demand_Unconstraining'!R7 -> 3.5897 | H7: ='02_Demand_Unconstraining'!S7 -> 1.3165 | I7: =_xlfn.XLOOKUP($A7,tbl_Catalog[sku_id],tbl_Catalog[z_score]) -> 1.645 | J7: =ROUNDUP(I7*SQRT(L2_Mean*(H7^2)+(G7^2)*(L2_Std^2)),0) -> 62 | K7: ='03_FBA_Nivel1_Transfer'!N7 -> 14 | L7: =_xlfn.CEILING.MATH(G7*L2_Mean+J7+K7,1) -> 346 | M7: =_xlfn.CEILING.MATH(G7*(L2_Mean+45)+J7+K7,1) -> 507 | N7: =_xlfn.CEILING.MATH(_xlfn.XLOOKUP($A7,tbl_Catalog[sku_id],tbl_Catalog[sku_moq_units])/_xlfn.XLOOKUP($A7,tbl_Catalog[sku_id],tbl_Catalog[master_carton_qty]),1) -> 3 | O7: =IF(G7>0,(F7-L7)/G7,999) -> -95.55116 | P7: =_xlfn.LET(_xlpm.ip_sys,$F7,_xlpm.rop_sys,$L7,_xlpm.s_max,$M7,_xlpm.m_qty,_xlfn.XLOOKUP($A7,tbl_Catalog[sku_id],tbl_Catalog[master_carton_qty]),_xlpm.moq,_xlfn.XLOOKUP($A7,tbl_Catalog[sku_id],tbl_Catalog[sku_moq_units]),IF(_xlpm.ip_sys<=_xlpm.rop_sys,_xlfn.CEILING.MATH(MAX(_xlpm.s_max-_xlpm.ip_sys,_xlpm.moq),_xlpm.m_qty),0)) -> 600 | Q7: =IF(P7>0,(P7/_xlfn.XLOOKUP($A7,tbl_Catalog[sku_id],tbl_Catalog[master_carton_qty]))*_xlfn.XLOOKUP($A7,tbl_Catalog[sku_id],tbl_Catalog[carton_volume_cbm]),0) -> 0.36 | R7: 400 | S7: 0 | T7: =S7*_xlfn.XLOOKUP($A7,tbl_Catalog[sku_id],tbl_Catalog[master_carton_qty]) -> 0 | U7: =R7+T7 -> 400 | V7: =IF(_xlfn.XLOOKUP($A7,tbl_Catalog[sku_id],tbl_Catalog[master_carton_qty])>0,U7/_xlfn.XLOOKUP($A7,tbl_Catalog[sku_id],tbl_Catalog[master_carton_qty]),0) -> 4 | W7: =V7*_xlfn.XLOOKUP($A7,tbl_Catalog[sku_id],tbl_Catalog[carton_volume_cbm]) -> 0.24 | X7: =IF(U7=0,"DEFERRED / NO PO",IF(S7>0,"BASE + TIER-A TOP-UP","BASE LOAD")) -> BASE LOAD | Y7: =IF(U7=0,"N/A",IF(AND(MOD(U7,_xlfn.XLOOKUP($A7,tbl_Catalog[sku_id],tbl_Catalog[master_carton_qty]))=0,U7>=_xlfn.XLOOKUP($A7,tbl_Catalog[sku_id],tbl_Catalog[sku_moq_units])),"MOQ OK","CHECK")) -> MOQ OK | Z7: =IF(U7=0,"N/A",IF((F7+U7)/MAX(0.1,G7)<=DOS_Cap,"DOS OK","MOQ OVERRIDE")) -> DOS OK | AA7: 300 | AB7: 0 | AC7: FALSE
A8: P01-RPN-S-NVY-WRZ | B8: P01-PCK-CUBE | C8: CZ | D8: 307 | E8: 0 | F8: ='03_FBA_Nivel1_Transfer'!E8+D8-E8 -> 307 | G8: ='02_Demand_Unconstraining'!R8 -> 0.9516 | H8: ='02_Demand_Unconstraining'!S8 -> 0.5725 | I8: =_xlfn.XLOOKUP($A8,tbl_Catalog[sku_id],tbl_Catalog[z_score]) -> 1.282 | J8: =ROUNDUP(I8*SQRT(L2_Mean*(H8^2)+(G8^2)*(L2_Std^2)),0) -> 14 | K8: ='03_FBA_Nivel1_Transfer'!N8 -> 4 | L8: =_xlfn.CEILING.MATH(G8*L2_Mean+J8+K8,1) -> 90 | M8: =_xlfn.CEILING.MATH(G8*(L2_Mean+45)+J8+K8,1) -> 133 | N8: =_xlfn.CEILING.MATH(_xlfn.XLOOKUP($A8,tbl_Catalog[sku_id],tbl_Catalog[sku_moq_units])/_xlfn.XLOOKUP($A8,tbl_Catalog[sku_id],tbl_Catalog[master_carton_qty]),1) -> 3 | O8: =IF(G8>0,(F8-L8)/G8,999) -> 228.03699 | P8: =_xlfn.LET(_xlpm.ip_sys,$F8,_xlpm.rop_sys,$L8,_xlpm.s_max,$M8,_xlpm.m_qty,_xlfn.XLOOKUP($A8,tbl_Catalog[sku_id],tbl_Catalog[master_carton_qty]),_xlpm.moq,_xlfn.XLOOKUP($A8,tbl_Catalog[sku_id],tbl_Catalog[sku_moq_units]),IF(_xlpm.ip_sys<=_xlpm.rop_sys,_xlfn.CEILING.MATH(MAX(_xlpm.s_max-_xlpm.ip_sys,_xlpm.moq),_xlpm.m_qty),0)) -> 0 | Q8: =IF(P8>0,(P8/_xlfn.XLOOKUP($A8,tbl_Catalog[sku_id],tbl_Catalog[master_carton_qty]))*_xlfn.XLOOKUP($A8,tbl_Catalog[sku_id],tbl_Catalog[carton_volume_cbm]),0) -> 0 | R8: 0 | S8: 0 | T8: =S8*_xlfn.XLOOKUP($A8,tbl_Catalog[sku_id],tbl_Catalog[master_carton_qty]) -> 0 | U8: =R8+T8 -> 0 | V8: =IF(_xlfn.XLOOKUP($A8,tbl_Catalog[sku_id],tbl_Catalog[master_carton_qty])>0,U8/_xlfn.XLOOKUP($A8,tbl_Catalog[sku_id],tbl_Catalog[master_carton_qty]),0) -> 0 | W8: =V8*_xlfn.XLOOKUP($A8,tbl_Catalog[sku_id],tbl_Catalog[carton_volume_cbm]) -> 0 | X8: =IF(U8=0,"DEFERRED / NO PO",IF(S8>0,"BASE + TIER-A TOP-UP","BASE LOAD")) -> DEFERRED / NO PO | Y8: =IF(U8=0,"N/A",IF(AND(MOD(U8,_xlfn.XLOOKUP($A8,tbl_Catalog[sku_id],tbl_Catalog[master_carton_qty]))=0,U8>=_xlfn.XLOOKUP($A8,tbl_Catalog[sku_id],tbl_Catalog[sku_moq_units])),"MOQ OK","CHECK")) -> N/A | Z8: =IF(U8=0,"N/A",IF((F8+U8)/MAX(0.1,G8)<=DOS_Cap,"DOS OK","MOQ OVERRIDE")) -> N/A | AA8: 0 | AB8: 0 | AC8: FALSE
A9: P01-RPN-S-OLV-ZIP | B9: P01-PCK-CUBE | C9: CZ | D9: 205 | E9: 0 | F9: ='03_FBA_Nivel1_Transfer'!E9+D9-E9 -> 205 | G9: ='02_Demand_Unconstraining'!R9 -> 0.9184 | H9: ='02_Demand_Unconstraining'!S9 -> 0.5455 | I9: =_xlfn.XLOOKUP($A9,tbl_Catalog[sku_id],tbl_Catalog[z_score]) -> 1.282 | J9: =ROUNDUP(I9*SQRT(L2_Mean*(H9^2)+(G9^2)*(L2_Std^2)),0) -> 14 | K9: ='03_FBA_Nivel1_Transfer'!N9 -> 4 | L9: =_xlfn.CEILING.MATH(G9*L2_Mean+J9+K9,1) -> 87 | M9: =_xlfn.CEILING.MATH(G9*(L2_Mean+45)+J9+K9,1) -> 129 | N9: =_xlfn.CEILING.MATH(_xlfn.XLOOKUP($A9,tbl_Catalog[sku_id],tbl_Catalog[sku_moq_units])/_xlfn.XLOOKUP($A9,tbl_Catalog[sku_id],tbl_Catalog[master_carton_qty]),1) -> 3 | O9: =IF(G9>0,(F9-L9)/G9,999) -> 128.48432 | P9: =_xlfn.LET(_xlpm.ip_sys,$F9,_xlpm.rop_sys,$L9,_xlpm.s_max,$M9,_xlpm.m_qty,_xlfn.XLOOKUP($A9,tbl_Catalog[sku_id],tbl_Catalog[master_carton_qty]),_xlpm.moq,_xlfn.XLOOKUP($A9,tbl_Catalog[sku_id],tbl_Catalog[sku_moq_units]),IF(_xlpm.ip_sys<=_xlpm.rop_sys,_xlfn.CEILING.MATH(MAX(_xlpm.s_max-_xlpm.ip_sys,_xlpm.moq),_xlpm.m_qty),0)) -> 0 | Q9: =IF(P9>0,(P9/_xlfn.XLOOKUP($A9,tbl_Catalog[sku_id],tbl_Catalog[master_carton_qty]))*_xlfn.XLOOKUP($A9,tbl_Catalog[sku_id],tbl_Catalog[carton_volume_cbm]),0) -> 0 | R9: 0 | S9: 0 | T9: =S9*_xlfn.XLOOKUP($A9,tbl_Catalog[sku_id],tbl_Catalog[master_carton_qty]) -> 0 | U9: =R9+T9 -> 0 | V9: =IF(_xlfn.XLOOKUP($A9,tbl_Catalog[sku_id],tbl_Catalog[master_carton_qty])>0,U9/_xlfn.XLOOKUP($A9,tbl_Catalog[sku_id],tbl_Catalog[master_carton_qty]),0) -> 0 | W9: =V9*_xlfn.XLOOKUP($A9,tbl_Catalog[sku_id],tbl_Catalog[carton_volume_cbm]) -> 0 | X9: =IF(U9=0,"DEFERRED / NO PO",IF(S9>0,"BASE + TIER-A TOP-UP","BASE LOAD")) -> DEFERRED / NO PO | Y9: =IF(U9=0,"N/A",IF(AND(MOD(U9,_xlfn.XLOOKUP($A9,tbl_Catalog[sku_id],tbl_Catalog[master_carton_qty]))=0,U9>=_xlfn.XLOOKUP($A9,tbl_Catalog[sku_id],tbl_Catalog[sku_moq_units])),"MOQ OK","CHECK")) -> N/A | Z9: =IF(U9=0,"N/A",IF((F9+U9)/MAX(0.1,G9)<=DOS_Cap,"DOS OK","MOQ OVERRIDE")) -> N/A | AA9: 0 | AB9: 0 | AC9: FALSE
A10: P01-RPN-S-OLV-WRZ | B10: P01-PCK-CUBE | C10: CZ | D10: 105 | E10: 0 | F10: ='03_FBA_Nivel1_Transfer'!E10+D10-E10 -> 192 | G10: ='02_Demand_Unconstraining'!R10 -> 0.5 | H10: ='02_Demand_Unconstraining'!S10 -> 0.5267 | I10: =_xlfn.XLOOKUP($A10,tbl_Catalog[sku_id],tbl_Catalog[z_score]) -> 1.282 | J10: =ROUNDUP(I10*SQRT(L2_Mean*(H10^2)+(G10^2)*(L2_Std^2)),0) -> 9 | K10: ='03_FBA_Nivel1_Transfer'!N10 -> 3 | L10: =_xlfn.CEILING.MATH(G10*L2_Mean+J10+K10,1) -> 50 | M10: =_xlfn.CEILING.MATH(G10*(L2_Mean+45)+J10+K10,1) -> 72 | N10: =_xlfn.CEILING.MATH(_xlfn.XLOOKUP($A10,tbl_Catalog[sku_id],tbl_Catalog[sku_moq_units])/_xlfn.XLOOKUP($A10,tbl_Catalog[sku_id],tbl_Catalog[master_carton_qty]),1) -> 3 | O10: =IF(G10>0,(F10-L10)/G10,999) -> 284 | P10: =_xlfn.LET(_xlpm.ip_sys,$F10,_xlpm.rop_sys,$L10,_xlpm.s_max,$M10,_xlpm.m_qty,_xlfn.XLOOKUP($A10,tbl_Catalog[sku_id],tbl_Catalog[master_carton_qty]),_xlpm.moq,_xlfn.XLOOKUP($A10,tbl_Catalog[sku_id],tbl_Catalog[sku_moq_units]),IF(_xlpm.ip_sys<=_xlpm.rop_sys,_xlfn.CEILING.MATH(MAX(_xlpm.s_max-_xlpm.ip_sys,_xlpm.moq),_xlpm.m_qty),0)) -> 0 | Q10: =IF(P10>0,(P10/_xlfn.XLOOKUP($A10,tbl_Catalog[sku_id],tbl_Catalog[master_carton_qty]))*_xlfn.XLOOKUP($A10,tbl_Catalog[sku_id],tbl_Catalog[carton_volume_cbm]),0) -> 0 | R10: 0 | S10: 0 | T10: =S10*_xlfn.XLOOKUP($A10,tbl_Catalog[sku_id],tbl_Catalog[master_carton_qty]) -> 0 | U10: =R10+T10 -> 0 | V10: =IF(_xlfn.XLOOKUP($A10,tbl_Catalog[sku_id],tbl_Catalog[master_carton_qty])>0,U10/_xlfn.XLOOKUP($A10,tbl_Catalog[sku_id],tbl_Catalog[master_carton_qty]),0) -> 0 | W10: =V10*_xlfn.XLOOKUP($A10,tbl_Catalog[sku_id],tbl_Catalog[carton_volume_cbm]) -> 0 | X10: =IF(U10=0,"DEFERRED / NO PO",IF(S10>0,"BASE + TIER-A TOP-UP","BASE LOAD")) -> DEFERRED / NO PO | Y10: =IF(U10=0,"N/A",IF(AND(MOD(U10,_xlfn.XLOOKUP($A10,tbl_Catalog[sku_id],tbl_Catalog[master_carton_qty]))=0,U10>=_xlfn.XLOOKUP($A10,tbl_Catalog[sku_id],tbl_Catalog[sku_moq_units])),"MOQ OK","CHECK")) -> N/A | Z10: =IF(U10=0,"N/A",IF((F10+U10)/MAX(0.1,G10)<=DOS_Cap,"DOS OK","MOQ OVERRIDE")) -> N/A | AA10: 0 | AB10: 0 | AC10: FALSE
A11: P01-RPN-S-SLT-ZIP | B11: P01-PCK-CUBE | C11: CZ | D11: 303 | E11: 0 | F11: ='03_FBA_Nivel1_Transfer'!E11+D11-E11 -> 303 | G11: ='02_Demand_Unconstraining'!R11 -> 0.819 | H11: ='02_Demand_Unconstraining'!S11 -> 0.4865 | I11: =_xlfn.XLOOKUP($A11,tbl_Catalog[sku_id],tbl_Catalog[z_score]) -> 1.282 | J11: =ROUNDUP(I11*SQRT(L2_Mean*(H11^2)+(G11^2)*(L2_Std^2)),0) -> 12 | K11: ='03_FBA_Nivel1_Transfer'!N11 -> 4 | L11: =_xlfn.CEILING.MATH(G11*L2_Mean+J11+K11,1) -> 78 | M11: =_xlfn.CEILING.MATH(G11*(L2_Mean+45)+J11+K11,1) -> 115 | N11: =_xlfn.CEILING.MATH(_xlfn.XLOOKUP($A11,tbl_Catalog[sku_id],tbl_Catalog[sku_moq_units])/_xlfn.XLOOKUP($A11,tbl_Catalog[sku_id],tbl_Catalog[master_carton_qty]),1) -> 3 | O11: =IF(G11>0,(F11-L11)/G11,999) -> 274.72527 | P11: =_xlfn.LET(_xlpm.ip_sys,$F11,_xlpm.rop_sys,$L11,_xlpm.s_max,$M11,_xlpm.m_qty,_xlfn.XLOOKUP($A11,tbl_Catalog[sku_id],tbl_Catalog[master_carton_qty]),_xlpm.moq,_xlfn.XLOOKUP($A11,tbl_Catalog[sku_id],tbl_Catalog[sku_moq_units]),IF(_xlpm.ip_sys<=_xlpm.rop_sys,_xlfn.CEILING.MATH(MAX(_xlpm.s_max-_xlpm.ip_sys,_xlpm.moq),_xlpm.m_qty),0)) -> 0 | Q11: =IF(P11>0,(P11/_xlfn.XLOOKUP($A11,tbl_Catalog[sku_id],tbl_Catalog[master_carton_qty]))*_xlfn.XLOOKUP($A11,tbl_Catalog[sku_id],tbl_Catalog[carton_volume_cbm]),0) -> 0 | R11: 0 | S11: 0 | T11: =S11*_xlfn.XLOOKUP($A11,tbl_Catalog[sku_id],tbl_Catalog[master_carton_qty]) -> 0 | U11: =R11+T11 -> 0 | V11: =IF(_xlfn.XLOOKUP($A11,tbl_Catalog[sku_id],tbl_Catalog[master_carton_qty])>0,U11/_xlfn.XLOOKUP($A11,tbl_Catalog[sku_id],tbl_Catalog[master_carton_qty]),0) -> 0 | W11: =V11*_xlfn.XLOOKUP($A11,tbl_Catalog[sku_id],tbl_Catalog[carton_volume_cbm]) -> 0 | X11: =IF(U11=0,"DEFERRED / NO PO",IF(S11>0,"BASE + TIER-A TOP-UP","BASE LOAD")) -> DEFERRED / NO PO | Y11: =IF(U11=0,"N/A",IF(AND(MOD(U11,_xlfn.XLOOKUP($A11,tbl_Catalog[sku_id],tbl_Catalog[master_carton_qty]))=0,U11>=_xlfn.XLOOKUP($A11,tbl_Catalog[sku_id],tbl_Catalog[sku_moq_units])),"MOQ OK","CHECK")) -> N/A | Z11: =IF(U11=0,"N/A",IF((F11+U11)/MAX(0.1,G11)<=DOS_Cap,"DOS OK","MOQ OVERRIDE")) -> N/A | AA11: 0 | AB11: 0 | AC11: FALSE
A12: P01-RPN-S-SLT-WRZ | B12: P01-PCK-CUBE | C12: CZ | D12: 291 | E12: 0 | F12: ='03_FBA_Nivel1_Transfer'!E12+D12-E12 -> 291 | G12: ='02_Demand_Unconstraining'!R12 -> 0.2836 | H12: ='02_Demand_Unconstraining'!S12 -> 0.1843 | I12: =_xlfn.XLOOKUP($A12,tbl_Catalog[sku_id],tbl_Catalog[z_score]) -> 1.282 | J12: =ROUNDUP(I12*SQRT(L2_Mean*(H12^2)+(G12^2)*(L2_Std^2)),0) -> 5 | K12: ='03_FBA_Nivel1_Transfer'!N12 -> 2 | L12: =_xlfn.CEILING.MATH(G12*L2_Mean+J12+K12,1) -> 29 | M12: =_xlfn.CEILING.MATH(G12*(L2_Mean+45)+J12+K12,1) -> 42 | N12: =_xlfn.CEILING.MATH(_xlfn.XLOOKUP($A12,tbl_Catalog[sku_id],tbl_Catalog[sku_moq_units])/_xlfn.XLOOKUP($A12,tbl_Catalog[sku_id],tbl_Catalog[master_carton_qty]),1) -> 3 | O12: =IF(G12>0,(F12-L12)/G12,999) -> 923.83639 | P12: =_xlfn.LET(_xlpm.ip_sys,$F12,_xlpm.rop_sys,$L12,_xlpm.s_max,$M12,_xlpm.m_qty,_xlfn.XLOOKUP($A12,tbl_Catalog[sku_id],tbl_Catalog[master_carton_qty]),_xlpm.moq,_xlfn.XLOOKUP($A12,tbl_Catalog[sku_id],tbl_Catalog[sku_moq_units]),IF(_xlpm.ip_sys<=_xlpm.rop_sys,_xlfn.CEILING.MATH(MAX(_xlpm.s_max-_xlpm.ip_sys,_xlpm.moq),_xlpm.m_qty),0)) -> 0 | Q12: =IF(P12>0,(P12/_xlfn.XLOOKUP($A12,tbl_Catalog[sku_id],tbl_Catalog[master_carton_qty]))*_xlfn.XLOOKUP($A12,tbl_Catalog[sku_id],tbl_Catalog[carton_volume_cbm]),0) -> 0 | R12: 0 | S12: 0 | T12: =S12*_xlfn.XLOOKUP($A12,tbl_Catalog[sku_id],tbl_Catalog[master_carton_qty]) -> 0 | U12: =R12+T12 -> 0 | V12: =IF(_xlfn.XLOOKUP($A12,tbl_Catalog[sku_id],tbl_Catalog[master_carton_qty])>0,U12/_xlfn.XLOOKUP($A12,tbl_Catalog[sku_id],tbl_Catalog[master_carton_qty]),0) -> 0 | W12: =V12*_xlfn.XLOOKUP($A12,tbl_Catalog[sku_id],tbl_Catalog[carton_volume_cbm]) -> 0 | X12: =IF(U12=0,"DEFERRED / NO PO",IF(S12>0,"BASE + TIER-A TOP-UP","BASE LOAD")) -> DEFERRED / NO PO | Y12: =IF(U12=0,"N/A",IF(AND(MOD(U12,_xlfn.XLOOKUP($A12,tbl_Catalog[sku_id],tbl_Catalog[master_carton_qty]))=0,U12>=_xlfn.XLOOKUP($A12,tbl_Catalog[sku_id],tbl_Catalog[sku_moq_units])),"MOQ OK","CHECK")) -> N/A | Z12: =IF(U12=0,"N/A",IF((F12+U12)/MAX(0.1,G12)<=DOS_Cap,"DOS OK","MOQ OVERRIDE")) -> N/A | AA12: 0 | AB12: 0 | AC12: FALSE
A13: P01-RPN-S-SND-ZIP | B13: P01-PCK-CUBE | C13: CZ | D13: 303 | E13: 0 | F13: ='03_FBA_Nivel1_Transfer'!E13+D13-E13 -> 303 | G13: ='02_Demand_Unconstraining'!R13 -> 0.615 | H13: ='02_Demand_Unconstraining'!S13 -> 0.361 | I13: =_xlfn.XLOOKUP($A13,tbl_Catalog[sku_id],tbl_Catalog[z_score]) -> 1.282 | J13: =ROUNDUP(I13*SQRT(L2_Mean*(H13^2)+(G13^2)*(L2_Std^2)),0) -> 9 | K13: ='03_FBA_Nivel1_Transfer'!N13 -> 3 | L13: =_xlfn.CEILING.MATH(G13*L2_Mean+J13+K13,1) -> 59 | M13: =_xlfn.CEILING.MATH(G13*(L2_Mean+45)+J13+K13,1) -> 86 | N13: =_xlfn.CEILING.MATH(_xlfn.XLOOKUP($A13,tbl_Catalog[sku_id],tbl_Catalog[sku_moq_units])/_xlfn.XLOOKUP($A13,tbl_Catalog[sku_id],tbl_Catalog[master_carton_qty]),1) -> 3 | O13: =IF(G13>0,(F13-L13)/G13,999) -> 396.74797 | P13: =_xlfn.LET(_xlpm.ip_sys,$F13,_xlpm.rop_sys,$L13,_xlpm.s_max,$M13,_xlpm.m_qty,_xlfn.XLOOKUP($A13,tbl_Catalog[sku_id],tbl_Catalog[master_carton_qty]),_xlpm.moq,_xlfn.XLOOKUP($A13,tbl_Catalog[sku_id],tbl_Catalog[sku_moq_units]),IF(_xlpm.ip_sys<=_xlpm.rop_sys,_xlfn.CEILING.MATH(MAX(_xlpm.s_max-_xlpm.ip_sys,_xlpm.moq),_xlpm.m_qty),0)) -> 0 | Q13: =IF(P13>0,(P13/_xlfn.XLOOKUP($A13,tbl_Catalog[sku_id],tbl_Catalog[master_carton_qty]))*_xlfn.XLOOKUP($A13,tbl_Catalog[sku_id],tbl_Catalog[carton_volume_cbm]),0) -> 0 | R13: 0 | S13: 0 | T13: =S13*_xlfn.XLOOKUP($A13,tbl_Catalog[sku_id],tbl_Catalog[master_carton_qty]) -> 0 | U13: =R13+T13 -> 0 | V13: =IF(_xlfn.XLOOKUP($A13,tbl_Catalog[sku_id],tbl_Catalog[master_carton_qty])>0,U13/_xlfn.XLOOKUP($A13,tbl_Catalog[sku_id],tbl_Catalog[master_carton_qty]),0) -> 0 | W13: =V13*_xlfn.XLOOKUP($A13,tbl_Catalog[sku_id],tbl_Catalog[carton_volume_cbm]) -> 0 | X13: =IF(U13=0,"DEFERRED / NO PO",IF(S13>0,"BASE + TIER-A TOP-UP","BASE LOAD")) -> DEFERRED / NO PO | Y13: =IF(U13=0,"N/A",IF(AND(MOD(U13,_xlfn.XLOOKUP($A13,tbl_Catalog[sku_id],tbl_Catalog[master_carton_qty]))=0,U13>=_xlfn.XLOOKUP($A13,tbl_Catalog[sku_id],tbl_Catalog[sku_moq_units])),"MOQ OK","CHECK")) -> N/A | Z13: =IF(U13=0,"N/A",IF((F13+U13)/MAX(0.1,G13)<=DOS_Cap,"DOS OK","MOQ OVERRIDE")) -> N/A | AA13: 0 | AB13: 0 | AC13: FALSE
A14: P01-RPN-S-SND-WRZ | B14: P01-PCK-CUBE | C14: CZ | D14: 304 | E14: 0 | F14: ='03_FBA_Nivel1_Transfer'!E14+D14-E14 -> 304 | G14: ='02_Demand_Unconstraining'!R14 -> 0.1791 | H14: ='02_Demand_Unconstraining'!S14 -> 0.1164 | I14: =_xlfn.XLOOKUP($A14,tbl_Catalog[sku_id],tbl_Catalog[z_score]) -> 1.282 | J14: =ROUNDUP(I14*SQRT(L2_Mean*(H14^2)+(G14^2)*(L2_Std^2)),0) -> 3 | K14: ='03_FBA_Nivel1_Transfer'!N14 -> 1 | L14: =_xlfn.CEILING.MATH(G14*L2_Mean+J14+K14,1) -> 18 | M14: =_xlfn.CEILING.MATH(G14*(L2_Mean+45)+J14+K14,1) -> 26 | N14: =_xlfn.CEILING.MATH(_xlfn.XLOOKUP($A14,tbl_Catalog[sku_id],tbl_Catalog[sku_moq_units])/_xlfn.XLOOKUP($A14,tbl_Catalog[sku_id],tbl_Catalog[master_carton_qty]),1) -> 3 | O14: =IF(G14>0,(F14-L14)/G14,999) -> 1596.8733 | P14: =_xlfn.LET(_xlpm.ip_sys,$F14,_xlpm.rop_sys,$L14,_xlpm.s_max,$M14,_xlpm.m_qty,_xlfn.XLOOKUP($A14,tbl_Catalog[sku_id],tbl_Catalog[master_carton_qty]),_xlpm.moq,_xlfn.XLOOKUP($A14,tbl_Catalog[sku_id],tbl_Catalog[sku_moq_units]),IF(_xlpm.ip_sys<=_xlpm.rop_sys,_xlfn.CEILING.MATH(MAX(_xlpm.s_max-_xlpm.ip_sys,_xlpm.moq),_xlpm.m_qty),0)) -> 0 | Q14: =IF(P14>0,(P14/_xlfn.XLOOKUP($A14,tbl_Catalog[sku_id],tbl_Catalog[master_carton_qty]))*_xlfn.XLOOKUP($A14,tbl_Catalog[sku_id],tbl_Catalog[carton_volume_cbm]),0) -> 0 | R14: 0 | S14: 0 | T14: =S14*_xlfn.XLOOKUP($A14,tbl_Catalog[sku_id],tbl_Catalog[master_carton_qty]) -> 0 | U14: =R14+T14 -> 0 | V14: =IF(_xlfn.XLOOKUP($A14,tbl_Catalog[sku_id],tbl_Catalog[master_carton_qty])>0,U14/_xlfn.XLOOKUP($A14,tbl_Catalog[sku_id],tbl_Catalog[master_carton_qty]),0) -> 0 | W14: =V14*_xlfn.XLOOKUP($A14,tbl_Catalog[sku_id],tbl_Catalog[carton_volume_cbm]) -> 0 | X14: =IF(U14=0,"DEFERRED / NO PO",IF(S14>0,"BASE + TIER-A TOP-UP","BASE LOAD")) -> DEFERRED / NO PO | Y14: =IF(U14=0,"N/A",IF(AND(MOD(U14,_xlfn.XLOOKUP($A14,tbl_Catalog[sku_id],tbl_Catalog[master_carton_qty]))=0,U14>=_xlfn.XLOOKUP($A14,tbl_Catalog[sku_id],tbl_Catalog[sku_moq_units])),"MOQ OK","CHECK")) -> N/A | Z14: =IF(U14=0,"N/A",IF((F14+U14)/MAX(0.1,G14)<=DOS_Cap,"DOS OK","MOQ OVERRIDE")) -> N/A | AA14: 0 | AB14: 0 | AC14: FALSE
A15: P01-RPN-S-TRC-ZIP | B15: P01-PCK-CUBE | C15: CZ | D15: 99 | E15: 0 | F15: ='03_FBA_Nivel1_Transfer'!E15+D15-E15 -> 224 | G15: ='02_Demand_Unconstraining'!R15 -> 0.4 | H15: ='02_Demand_Unconstraining'!S15 -> 0.4025 | I15: =_xlfn.XLOOKUP($A15,tbl_Catalog[sku_id],tbl_Catalog[z_score]) -> 1.282 | J15: =ROUNDUP(I15*SQRT(L2_Mean*(H15^2)+(G15^2)*(L2_Std^2)),0) -> 7 | K15: ='03_FBA_Nivel1_Transfer'!N15 -> 3 | L15: =_xlfn.CEILING.MATH(G15*L2_Mean+J15+K15,1) -> 40 | M15: =_xlfn.CEILING.MATH(G15*(L2_Mean+45)+J15+K15,1) -> 58 | N15: =_xlfn.CEILING.MATH(_xlfn.XLOOKUP($A15,tbl_Catalog[sku_id],tbl_Catalog[sku_moq_units])/_xlfn.XLOOKUP($A15,tbl_Catalog[sku_id],tbl_Catalog[master_carton_qty]),1) -> 3 | O15: =IF(G15>0,(F15-L15)/G15,999) -> 460 | P15: =_xlfn.LET(_xlpm.ip_sys,$F15,_xlpm.rop_sys,$L15,_xlpm.s_max,$M15,_xlpm.m_qty,_xlfn.XLOOKUP($A15,tbl_Catalog[sku_id],tbl_Catalog[master_carton_qty]),_xlpm.moq,_xlfn.XLOOKUP($A15,tbl_Catalog[sku_id],tbl_Catalog[sku_moq_units]),IF(_xlpm.ip_sys<=_xlpm.rop_sys,_xlfn.CEILING.MATH(MAX(_xlpm.s_max-_xlpm.ip_sys,_xlpm.moq),_xlpm.m_qty),0)) -> 0 | Q15: =IF(P15>0,(P15/_xlfn.XLOOKUP($A15,tbl_Catalog[sku_id],tbl_Catalog[master_carton_qty]))*_xlfn.XLOOKUP($A15,tbl_Catalog[sku_id],tbl_Catalog[carton_volume_cbm]),0) -> 0 | R15: 0 | S15: 0 | T15: =S15*_xlfn.XLOOKUP($A15,tbl_Catalog[sku_id],tbl_Catalog[master_carton_qty]) -> 0 | U15: =R15+T15 -> 0 | V15: =IF(_xlfn.XLOOKUP($A15,tbl_Catalog[sku_id],tbl_Catalog[master_carton_qty])>0,U15/_xlfn.XLOOKUP($A15,tbl_Catalog[sku_id],tbl_Catalog[master_carton_qty]),0) -> 0 | W15: =V15*_xlfn.XLOOKUP($A15,tbl_Catalog[sku_id],tbl_Catalog[carton_volume_cbm]) -> 0 | X15: =IF(U15=0,"DEFERRED / NO PO",IF(S15>0,"BASE + TIER-A TOP-UP","BASE LOAD")) -> DEFERRED / NO PO | Y15: =IF(U15=0,"N/A",IF(AND(MOD(U15,_xlfn.XLOOKUP($A15,tbl_Catalog[sku_id],tbl_Catalog[master_carton_qty]))=0,U15>=_xlfn.XLOOKUP($A15,tbl_Catalog[sku_id],tbl_Catalog[sku_moq_units])),"MOQ OK","CHECK")) -> N/A | Z15: =IF(U15=0,"N/A",IF((F15+U15)/MAX(0.1,G15)<=DOS_Cap,"DOS OK","MOQ OVERRIDE")) -> N/A | AA15: 0 | AB15: 0 | AC15: FALSE
A16: P01-RPN-S-TRC-WRZ | B16: P01-PCK-CUBE | C16: CZ | D16: 301 | E16: 0 | F16: ='03_FBA_Nivel1_Transfer'!E16+D16-E16 -> 301 | G16: ='02_Demand_Unconstraining'!R16 -> 0.1483 | H16: ='02_Demand_Unconstraining'!S16 -> 0.0873 | I16: =_xlfn.XLOOKUP($A16,tbl_Catalog[sku_id],tbl_Catalog[z_score]) -> 1.282 | J16: =ROUNDUP(I16*SQRT(L2_Mean*(H16^2)+(G16^2)*(L2_Std^2)),0) -> 3 | K16: ='03_FBA_Nivel1_Transfer'!N16 -> 1 | L16: =_xlfn.CEILING.MATH(G16*L2_Mean+J16+K16,1) -> 16 | M16: =_xlfn.CEILING.MATH(G16*(L2_Mean+45)+J16+K16,1) -> 22 | N16: =_xlfn.CEILING.MATH(_xlfn.XLOOKUP($A16,tbl_Catalog[sku_id],tbl_Catalog[sku_moq_units])/_xlfn.XLOOKUP($A16,tbl_Catalog[sku_id],tbl_Catalog[master_carton_qty]),1) -> 3 | O16: =IF(G16>0,(F16-L16)/G16,999) -> 1921.7802 | P16: =_xlfn.LET(_xlpm.ip_sys,$F16,_xlpm.rop_sys,$L16,_xlpm.s_max,$M16,_xlpm.m_qty,_xlfn.XLOOKUP($A16,tbl_Catalog[sku_id],tbl_Catalog[master_carton_qty]),_xlpm.moq,_xlfn.XLOOKUP($A16,tbl_Catalog[sku_id],tbl_Catalog[sku_moq_units]),IF(_xlpm.ip_sys<=_xlpm.rop_sys,_xlfn.CEILING.MATH(MAX(_xlpm.s_max-_xlpm.ip_sys,_xlpm.moq),_xlpm.m_qty),0)) -> 0 | Q16: =IF(P16>0,(P16/_xlfn.XLOOKUP($A16,tbl_Catalog[sku_id],tbl_Catalog[master_carton_qty]))*_xlfn.XLOOKUP($A16,tbl_Catalog[sku_id],tbl_Catalog[carton_volume_cbm]),0) -> 0 | R16: 0 | S16: 0 | T16: =S16*_xlfn.XLOOKUP($A16,tbl_Catalog[sku_id],tbl_Catalog[master_carton_qty]) -> 0 | U16: =R16+T16 -> 0 | V16: =IF(_xlfn.XLOOKUP($A16,tbl_Catalog[sku_id],tbl_Catalog[master_carton_qty])>0,U16/_xlfn.XLOOKUP($A16,tbl_Catalog[sku_id],tbl_Catalog[master_carton_qty]),0) -> 0 | W16: =V16*_xlfn.XLOOKUP($A16,tbl_Catalog[sku_id],tbl_Catalog[carton_volume_cbm]) -> 0 | X16: =IF(U16=0,"DEFERRED / NO PO",IF(S16>0,"BASE + TIER-A TOP-UP","BASE LOAD")) -> DEFERRED / NO PO | Y16: =IF(U16=0,"N/A",IF(AND(MOD(U16,_xlfn.XLOOKUP($A16,tbl_Catalog[sku_id],tbl_Catalog[master_carton_qty]))=0,U16>=_xlfn.XLOOKUP($A16,tbl_Catalog[sku_id],tbl_Catalog[sku_moq_units])),"MOQ OK","CHECK")) -> N/A | Z16: =IF(U16=0,"N/A",IF((F16+U16)/MAX(0.1,G16)<=DOS_Cap,"DOS OK","MOQ OVERRIDE")) -> N/A | AA16: 0 | AB16: 0 | AC16: FALSE
